Workbook
Name cmp_conditional: Lookups!$B$30
Name cmp_suitable: Lookups!$B$29
Name mcp_min_compliance: Lookups!$B$31
Name p_autonomy: Scoping!$C$20
Name p_background: Scoping!$C$21
Name p_confidential: Scoping!$C$12
Name p_decisions: Scoping!$C$16
Name p_downstream: Scoping!$C$15
Name p_eu: Scoping!$C$13
Name p_finetune: Scoping!$C$18
Name p_local: Scoping!$C$22
Name p_locus: Scoping!$C$25
Name p_mcp: Scoping!$C$27
Name p_memory: Scoping!$C$23
Name p_multiagent: Scoping!$C$24
Name p_open: Scoping!$C$28
Name p_personal: Scoping!$C$11
Name p_provider: Scoping!$C$9
Name p_rag: Scoping!$C$17
Name p_role: Scoping!$C$26
Name p_stage: Scoping!$C$10
Name p_tools: Scoping!$C$19
Name p_users: Scoping!$C$14
Name t_readiness: Lookups!$B$25
Name t_residual: Lookups!$B$26

Sheet README & Logic
A1: LLM & Agent Security Assessment Workbook - Logic (v0.6.8-r4, repaired)
A3: Purpose | B3: Assess an LLM- or agent-powered integration before pilot, production, or material change.
A4: Quick start (approx. 2-3 h first pass) | B4: 1) Scoping sheet: system header plus 19 profile questions (10-15 min, system owner + assessor). Applicability of every control is derived automatically; grey rows are out of scope; answers outside the dropdown lists count as open questions. 2) Assessment Matrix: answer the white rows Yes / Partial / No and attach evidence for every Yes or Partial (60-90 min). Detail columns (scoring, remediation bookkeeping, related/guidance, exemption fields) ship collapsed; expand the column groups with the + buttons above the grid when you need them. 3) MCP checklists if S19 = Yes. 4) Dashboard decision and sign-off.
A5: Roles | B5: System owner fills the Scoping header and answers. Assessor answers controls. Security/legal review 1.3, 2.5, 2.7, 5.4, and domain 7. The accountable risk owner signs the Dashboard and is the only role that may grant exemptions. A control owned by another department and awaiting its review stays applicable; ownership is never a reason to mark a control out of scope.
A6: Scoping logic | B6: Each control carries an applicability rule referencing the Scoping answers (shown in the Applicability column). Unanswered Scoping questions never deactivate a control (fail-safe: in doubt, a control stays applicable), and out-of-list answers count as open questions. To overrule the automatic result for a single row, use the Override column and justify it in Notes.
A7: Hard gates | B7: Any applicable Blocker control answered No results in a BLOCK. A Blocker answered Partial is a BLOCK in Production and an ESCALATE in Pilot/PoC. Any Major answered No is an ESCALATE. Remediation closes a gate by re-testing and re-answering the control (Status alone never clears a gate).
A8: Exemption procedure | B8: To exempt a gate formally: set Status = Accepted Risk and fill the exemption columns X-Z (reference: risk-owner decision, committee minute, or ticket; approver; date). The Gate Flag then shows the stage-sensitive gate with an (exempted) suffix, the Dashboard counts it, and the decision can move to CONDITIONAL APPROVAL, never to silent approval. Exemptions with missing reference/approver/date are flagged per row and block completion. Remediation closes a gate by re-testing and re-answering the control. Three distinct review decisions use these columns: an applicability review of an auto-applicable Blocker (override needs X-Z), an approved criticality variation below the shipped baseline (needs rationale in Notes and approver in Y), and acceptance of an unmet applicable Blocker or Major requirement (Accepted Risk + X-Z converts the gate into a counted exemption and caps the decision at CONDITIONAL APPROVAL). For Moderate and Minor controls, Status = Accepted Risk documents the acceptance in the residual view; it is not a formal gate exemption and does not by itself force a conditional decision. It still needs reference, approver and date in X-Z, as does every other Status = Accepted Risk entry (integrity check).
A9: Scoring | B9: Yes = 1.0, Partial = 0.5, No = 0.0. Weight follows Criticality automatically (Lookups table; change Criticality and Weight updates). Likelihood and Impact are assessor inputs with 1-5 scales defined on Lookups; the shipped values are generic defaults, adjust them per system. Residual per answered control = Weight x Likelihood x Impact x (1 - score); the Dashboard aggregates this as a weighted residual-exposure / control-gap index - a relative prioritization measure, not a calibrated loss estimate. Unanswered controls contribute their full exposure separately. The policy thresholds on Lookups (readiness minima, residual thresholds, MCP minimum compliance rate, Comparator cutoffs) are validated: blank, non-numeric, out-of-range or inconsistently ordered settings are integrity flags that hold the decision, and data validation guides legitimate edits.
A10: Decision | B10: INCOMPLETE until Scoping is complete and valid, every applicable control has a response, integrity checks pass, and (if S19 = Yes) every MCP side has an explicit Required selection and each required side is assessed with complete context. Contradictions between S19 and the Required switches block completion; a required checklist is never silently ignored. BLOCKED if any blocker is open or a required MCP side verdicts NO-GO, i.e. an open mandatory checkpoint or a compliance rate below the Lookups minimum (blocking verdicts outrank evidence-only conditions). CONDITIONAL APPROVAL if readiness < minimum, escalations or exemptions exist, evidence is missing, a control sits at/above the residual threshold, or an MCP side verdicts CONDITIONAL GO. Otherwise APPROVABLE. The final decision is signed off by the accountable risk owner on the Dashboard. Invalid or error-valued shared configuration holds both deployment and sourcing. Operational answers, evidence, status and remediation/exemption inputs are checked for calculation errors without making unused operational metadata a sourcing dependency. Required MCP sides have separate context, answer/evidence and exclusion-review validity states; errors cannot count as clean evidence. A confirmed mandatory failure remains visible alongside incomplete inputs.
A11: Assessment object | B11: Score the entire LLM system, not just the base model: model, provider, deployment, prompts, RAG/vector DB, tools/plugins/agents, APIs, data flows, logging, and operations.
A12: Agentic scope | B12: Domain 9 (Agentic AI) activates by autonomy and by capability: an autonomy level other than None activates the core agentic controls, while 9.4 (tools, S11), 9.5 (local device access, S14), 9.7 (persistent memory, S15) and 9.11 (multi-agent / MCP, S16 or S19) activate on their own triggers even when S12 = None. It covers autonomy classification, human-in-the-loop gates, agent identity and least privilege, tool allowlisting, sandboxing and egress control, indirect prompt injection, persistent memory, background operation limits, action logging, kill switch, multi-agent / MCP supply chain, autonomy anomaly monitoring, and agent credential lifecycle.
A13: Evidence principle | B13: Every Yes or Partial should be supported by evidence: architecture diagram, contract/DPA, model card, SBOM/AIBOM, audit report, test report, ticket, policy, or log sample. The Guidance column states the expected evidence per control. Missing evidence is counted on the Dashboard and prevents an unconditional approval.
A14: Glossary | B14: Blocker: non-negotiable gate. Major: requires escalation when unmet. Moderate/Minor: gradable. Partial: defined per control in the Guidance column. Autonomy (S12): Assisted = human approves every action; Supervised = human approves material actions; Autonomous = acts without per-action approval. Role (S18): Assist = output informs a human; Steer = output controls or prioritizes a process; Intervene = output executes changes in systems or the physical world. Verdicts: INCOMPLETE / BLOCKED / CONDITIONAL APPROVAL / APPROVABLE.
... A16: Print | B16: Print setup is landscape, fit-to-width, with repeating header rows (approx. 20 pages for the full workbook in a v0.6.3 headless render; re-verify the current page layout before circulating hard copies). Native Microsoft Excel print and interaction acceptance is still pending.
A17: Useful reference mappings
A18: OWASP LLM Top 10 | B18: Map application threat scenarios such as prompt injection, insecure output handling, model denial of service, supply chain, sensitive information disclosure, excessive agency, and vector/embedding weaknesses. Per-control mapping sits in the Guidance column.
A19: OWASP Agentic Security | B19: Threats and mitigations specific to agentic systems (tool misuse, memory poisoning, identity spoofing, cascading agent failures).
A20: NIST AI RMF / GenAI Profile | B20: Governance, mapping, measurement, and management of GenAI risks.
A21: MITRE ATLAS | B21: Adversarial AI tactics and techniques for threat models and test plans.
A22: EU AI Act / GPAI | B22: Role classification, high-risk duties, GPAI obligations, transparency, logging, human oversight, and compliance roadmap.
A23: Reference | B23: Plain-text URL
A24: OWASP Top 10 for LLM Applications | B24: https://owasp.org/www-project-top-10-for-large-language-model-applications/
A25: OWASP GenAI Security Project | B25: https://genai.owasp.org/
A26: NIST AI Risk Management Framework | B26: https://www.nist.gov/itl/ai-risk-management-framework
A27: NIST AI RMF Generative AI Profile | B27: https://www.nist.gov/publications/artificial-intelligence-risk-management-framework-generative-artificial-intelligence
A28: MITRE ATLAS | B28: https://atlas.mitre.org/
A29: European Commission AI Act overview | B29: https://digital-strategy.ec.europa.eu/en/policies/regulatory-framework-ai
... A34: Migration between versions | B34: Sheet 'Migration': paste the old version's sheets as values into the 'Old ...' sheets, check the status lines, then copy each blue block to the named target cell with Paste Special > Values + Skip blanks (unprotect the target sheet first, no password). Rows are matched by control ID and the Assessment Matrix columns by header text, so controls or columns that moved or are new keep the current values. Template-owned cells (criticality baseline, MCP severity, lookups) are not migrated.

Sheet Scoping
A1: Scoping - answer this sheet first, it steers the whole assessment
B3: System / use case name
B4: Assessor / accountable owner
B5: Date
B6: Assessment version (of the system / this assessment)
A8: ID | B8: Question | C8: Answer | D8: What the answer switches | E8: Validity
A9: S1 | B9: Provider / deployment model | D9: Provider, contract, and supply-chain controls (2.2, 2.3, 2.5, 2.7, 3.9, 5.2, 5.6, 5.8, 7.2, 7.3). | E9: =IF(IFERROR(C9="",TRUE()),"blank",IF(IFERROR(OR(C9="External SaaS / API",C9="COTS (on-prem or managed)",C9="Self-hosted / open weights",C9="Internal development"),FALSE()),"valid","invalid")) -> blank
A10: S2 | B10: Stage of use | D10: Production-only operations controls (2.4, 2.6, 5.1, 5.3, 6.1, 6.4, 6.5, 6.6, 8.2, 8.5). | E10: =IF(IFERROR(C10="",TRUE()),"blank",IF(IFERROR(OR(C10="Pilot / PoC",C10="Production"),FALSE()),"valid","invalid")) -> blank
A11: S3 | B11: Personal data is processed | D11: Privacy controls (4.5, 6.1, 7.1, 7.2). | E11: =IF(IFERROR(C11="",TRUE()),"blank",IF(IFERROR(OR(C11="Yes",C11="No"),FALSE()),"valid","invalid")) -> blank
A12: S4 | B12: Confidential or regulated data is processed | D12: Disclosure and monitoring controls (4.5, 6.1, 6.5, 7.2). S4 = Yes also raises control 2.7 to Blocker criticality. | E12: =IF(IFERROR(C12="",TRUE()),"blank",IF(IFERROR(OR(C12="Yes",C12="No"),FALSE()),"valid","invalid")) -> blank
A13: S5 | B13: EU market or EU users are in scope | D13: AI Act controls (1.3, 7.4). | E13: =IF(IFERROR(C13="",TRUE()),"blank",IF(IFERROR(OR(C13="Yes",C13="No"),FALSE()),"valid","invalid")) -> blank
A14: S6 | B14: User group | D14: Abuse, volume, and external-exposure controls (4.4, 6.3). | E14: =IF(IFERROR(C14="",TRUE()),"blank",IF(IFERROR(OR(C14="Internal (limited group)",C14="Internal (broad)",C14="External / public"),FALSE()),"valid","invalid")) -> blank
A15: S7 | B15: Outputs feed downstream systems or are executed (code, SQL, workflows, mails) | D15: Output handling controls (3.6, 4.9). | E15: =IF(IFERROR(C15="",TRUE()),"blank",IF(IFERROR(OR(C15="Yes",C15="No"),FALSE()),"valid","invalid")) -> blank
A16: S8 | B16: Output supports consequential decisions about people | D16: Human oversight control (1.4); indicator for AI Act high-risk review in 1.3. | E16: =IF(IFERROR(C16="",TRUE()),"blank",IF(IFERROR(OR(C16="Yes",C16="No"),FALSE()),"valid","invalid")) -> blank
A17: S9 | B17: RAG, vector database, or knowledge base is used | D17: Retrieval controls (3.5, 4.3). | E17: =IF(IFERROR(C17="",TRUE()),"blank",IF(IFERROR(OR(C17="Yes",C17="No"),FALSE()),"valid","invalid")) -> blank
A18: S10 | B18: Fine-tuning or model adaptation is performed | D18: Training-data controls (4.3, 5.5). | E18: =IF(IFERROR(C18="",TRUE()),"blank",IF(IFERROR(OR(C18="Yes",C18="No"),FALSE()),"valid","invalid")) -> blank
A19: S11 | B19: Tools, plugins, or function calling are used | D19: Tool controls (3.2, 3.6, 3.9, 4.6, 9.4). | E19: =IF(IFERROR(C19="",TRUE()),"blank",IF(IFERROR(OR(C19="Yes",C19="No"),FALSE()),"valid","invalid")) -> blank
A20: S12 | B20: Autonomy level of the system | D20: Activates autonomy-dependent agent controls and 1.5. Tools, local access, memory and MCP can keep specific controls relevant even when autonomy is None. | E20: =IF(IFERROR(C20="",TRUE()),"blank",IF(IFERROR(OR(C20="None (chat or single completions)",C20="Assisted (human approves every action)",C20="Supervised (human approves material actions)",C20="Autonomous (acts without per-action approval)"),FALSE()),"valid","invalid")) -> blank
A21: S13 | B21: Continuous or scheduled background operation (agent runs without a user session) | D21: Background limits and kill-switch emphasis (9.8). | E21: =IF(IFERROR(C21="",TRUE()),"blank",IF(IFERROR(OR(C21="Yes",C21="No"),FALSE()),"valid","invalid")) -> blank
A22: S14 | B22: Local device access (files, shell, browser control) | D22: Isolation and egress control (9.5). | E22: =IF(IFERROR(C22="",TRUE()),"blank",IF(IFERROR(OR(C22="Yes",C22="No"),FALSE()),"valid","invalid")) -> blank
A23: S15 | B23: Persistent memory across sessions | D23: Memory governance (9.7). | E23: =IF(IFERROR(C23="",TRUE()),"blank",IF(IFERROR(OR(C23="Yes",C23="No"),FALSE()),"valid","invalid")) -> blank
A24: S16 | B24: Multi-agent setup or external agents are used (regardless of protocol) | D24: Agent supply-chain control (9.11); domain 9 emphasis. MCP itself is declared separately in S19. | E24: =IF(IFERROR(C24="",TRUE()),"blank",IF(IFERROR(OR(C24="Yes",C24="No"),FALSE()),"valid","invalid")) -> blank
A25: S17 | B25: Primary deployment locus | D25: Positions the system in the AI Defense Matrix; Production / OT proximity activates control 3.7. | E25: =IF(IFERROR(C25="",TRUE()),"blank",IF(IFERROR(OR(C25="End user client / endpoint",C25="Cloud or SaaS tenant",C25="Own data center / servers",C25="Network or gateway (inline)",C25="Production / OT proximity"),FALSE()),"valid","invalid")) -> blank
A26: S18 | B26: Operational role of the output | D26: Sets verdict strictness (readiness minimum and residual threshold, see Lookups); Steer/Intervene keeps human-oversight control 1.4 applicable. | E26: =IF(IFERROR(C26="",TRUE()),"blank",IF(IFERROR(OR(C26="Assist (informs a human)",C26="Steer (controls or prioritizes a process)",C26="Intervene (executes changes in systems or the physical world)"),FALSE()),"valid","invalid")) -> blank
A27: S19 | B27: MCP (Model Context Protocol) servers or clients are used | D27: Authoritative MCP scope: the MCP checklists become hard gates; each side must be explicitly Required Yes/No; feeds 9.11. | E27: =IF(IFERROR(C27="",TRUE()),"blank",IF(IFERROR(OR(C27="Yes",C27="No"),FALSE()),"valid","invalid")) -> blank
B28: Open or invalid scoping questions | C28: =COUNTIF($E$9:$E$27,"blank")+COUNTIF($E$9:$E$27,"invalid") -> 19
B29: Consistency hint | C29: =IFERROR(IF(AND($C$20="None (chat or single completions)",OR($C$21="Yes",$C$22="Yes",$C$24="Yes")),"Check S12: background operation, local access, or multi-agent answered Yes although autonomy is None.",""),"")
B30: Consistency hint | C30: =IFERROR(IF(AND($C$19="No",$C$20<>"None (chat or single completions)",$C$20<>""),"Check S11/S12: autonomy above None usually implies tool use, but S11 = No.",""),"")
B31: Consistency hint | C31: =IFERROR(IF(AND($C$24="Yes",$C$19="No"),"Check S16/S11: multi-agent or MCP setups use tools or function calling, but S11 = No.",""),"")
B32: Consistency hint | C32: =IFERROR(IF(AND($C$25="Production / OT proximity",$C$26="Assist (informs a human)"),"Check S17/S18: OT-adjacent deployment whose output only informs a human.",""),"")
B33: Consistency hint (hard) | C33: =IFERROR(IF(AND($C$27="Yes",'MCP Server Checklist'!$I$2="No",'MCP Client Checklist'!$I$2="No"),"S19 = Yes but neither MCP side is marked Required: the decision stays INCOMPLETE. Mark at least one side Required and assess it, or set S19 = No.",""),"")
B34: Consistency hint (hard) | C34: =IFERROR(IF(AND($C$27="No",OR('MCP Server Checklist'!$I$2="Yes",'MCP Client Checklist'!$I$2="Yes")),"S19 = No but an MCP side is marked Required: the decision stays INCOMPLETE. A required checklist is never silently ignored: set the side to Required = No or answer S19 = Yes.",""),"")
B35: Consistency hint | C35: =IFERROR(IF(AND($C$24="Yes",$C$27="No"),"Check S16/S19: multi-agent setups often use MCP; confirm no agent connects to MCP servers or clients.",""),"")
B36: Consistency hint | C36: =IF(COUNTIF($E$9:$E$27,"invalid")>0,"One or more scoping answers are outside the allowed lists; they count as open questions.","")
A38: Hint classes | B38: Soft hints flag unlikely combinations to review. Hard contradictions (S19 vs the Required switches) are binding: they keep the decision at INCOMPLETE until resolved, so a required checklist can never be silently excluded.

Sheet Assessment Matrix
A1: ID | B1: Domain | C1: Applicability | D1: Control / Assessment Question | E1: Criticality | F1: Weight | G1: Likelihood (1-5) | H1: Impact (1-5) | I1: Applicable? | J1: Override (applicability) | K1: Response | L1: Implementation Score | M1: Residual Risk | N1: Gate Flag | O1: Evidence / Link | P1: Owner | Q1: Remediation / Decision | R1: Target Date | S1: Status | T1: Notes | U1: Row Check | V1: Related controls (scope) | W1: Guidance: what good looks like, evidence, Partial definition, framework mapping | X1: Exemption reference | Y1: Exemption approver | Z1: Exemption date | AA1: Integrity flag: N/A on applicable (ID) | AB1: Integrity flag: override without reason (ID) | AC1: Integrity flag: invalid value / exemption gap / floor (ID + reason) | AD1: Baseline criticality (v0.6.5 ship state) | AE1: Unused helper column (reserved; empty since v0.6.8-r1) | AF1: Shared configuration validity flag (typed) | AG1: Editable-input error flag (typed) | AH1: Config flag IDs (typed) | AI1: Automatic applicability before override | AJ1: Invalid response flag | AK1: Likelihood / impact validity flag | AL1: Status validity flag | AM1: Exemption metadata validity flag | AN1: Applicable N/A flag | AO1: Override rationale flag | AP1: Missing / unusable evidence flag | AQ1: Operational row integrity flag (typed) | AR1: Valid applicable answer (1/0) | AS1: Readiness numerator | AT1: Readiness denominator | AU1: Input error locations | AV1: Configuration issue details | AW1: Operational issue details
A2: 1.1 | B2: Use Case & Data | C2: Auto: always | D2: Business purpose, accountable owner, users, and intended decisions are documented. | E2: Major | F2: =IFERROR(IF($E2="Blocker",Lookups!$B$8,IF($E2="Major",Lookups!$B$9,IF($E2="Moderate",Lookups!$B$10,IF($E2="Minor",Lookups!$B$11,0)))),0) -> 4 | G2: 3 | H2: 3 | I2: =IFERROR(IF(OR($J2="Yes",$J2="No"),$J2,"Yes"),"Yes") -> Yes | L2: =IFERROR(IF(OR($I2="No",$K2="N/A"),"",IF($K2="Yes",1,IF($K2="Partial",0.5,IF($K2="No",0,"")))),"") | M2: =IFERROR(IF(OR($I2="No",$K2="N/A"),"",$F2*IF(OR($G2="",NOT(ISNUMBER($G2))),3,$G2)*IF(OR($H2="",NOT(ISNUMBER($H2))),3,$H2)*IF($K2="",1,1-$L2)),"") -> 36 | N2: =IFERROR(IF(OR($I2="No",$K2="N/A",$K2=""),"",IF(AND(IFERROR(AND($S2="Accepted Risk",$AM2=0),FALSE()),OR(AND($E2="Blocker",OR($K2="No",$K2="Partial")),AND($E2="Major",$K2="No"))),IF(AND($E2="Blocker",$K2="No"),"BLOCK",IF(AND($E2="Blocker",$K2="Partial"),IF(p_stage="Pilot / PoC","ESCALATE","BLOCK"),IF(AND($E2="Major",$K2="No"),"ESCALATE","")))&" (exempted)",IF(AND($E2="Blocker",$K2="No"),"BLOCK",IF(AND($E2="Blocker",$K2="Partial"),IF(p_stage="Pilot / PoC","ESCALATE","BLOCK"),IF(AND($E2="Major",$K2="No"),"ESCALATE",""))))),"") | U2: =_xlfn.TEXTJOIN("; ",TRUE(),$AV2,$AW2,IF($AP2>0,"Evidence missing or unusable","")) | W2: Good: one-page charter naming business purpose, accountable owner, user groups, and intended decisions. Evidence: charter, Confluence page, product ticket. Partial: documented but owner or intended decisions unclear. Advisory map (partial): NIST AI RMF Govern. | AA2: =IF($AN2>0,$A2,"") | AB2: =IF($AO2>0,$A2,"") | AC2: =IF($AQ2>0,$A2&" ("&$U2&")","") | AD2: Major | AF2: =IF(OR(IFERROR(NOT(OR($J2="",$J2="Yes",$J2="No")),TRUE()),IFERROR(IF($E2="",$I2="Yes",NOT(OR($E2="Blocker",$E2="Major",$E2="Moderate",$E2="Minor"))),TRUE()),IFERROR(IF($J2<>"",$T2="",FALSE()),TRUE()),IFERROR(IF(AND($A2="2.7",$I2="Yes",p_confidential="Yes"),$E2<>"Blocker",FALSE()),TRUE()),IFERROR(IF(AND($A2="5.8",$I2="Yes"),OR($E2="Moderate",$E2="Minor"),FALSE()),TRUE()),IF(IFERROR(AND($J2="No",$AI2="Yes",OR($AD2="Blocker",AND($A2="2.7",p_confidential="Yes"))),FALSE()),NOT(AND(IFERROR($X2<>"",FALSE()),IFERROR($Y2<>"",FALSE()),IFERROR(AND(ISNUMBER($Z2),$Z2>=DATE(2020,1,1),$Z2<=DATE(2100,12,31)),FALSE()))),FALSE()),IF(IFERROR(IF(OR($E2="Blocker",$E2="Major",$E2="Moderate",$E2="Minor"),$F2<IF($AD2="Blocker",Lookups!$B$8,IF($AD2="Major",Lookups!$B$9,IF($AD2="Moderate",Lookups!$B$10,Lookups!$B$11))),FALSE()),FALSE()),NOT(AND(IFERROR($T2<>"",FALSE()),IFERROR($Y2<>"",FALSE()),IF(IFERROR($Z2<>"",FALSE()),IFERROR(AND(ISNUMBER($Z2),$Z2>=DATE(2020,1,1),$Z2<=DATE(2100,12,31)),FALSE()),NOT(ISERROR($Z2))))),FALSE())),1,0) -> 0 | AG2: =IF(OR(ISERROR($E2),ISERROR($G2),ISERROR($H2),ISERROR($J2),ISERROR($K2),ISERROR($O2),ISERROR($P2),ISERROR($Q2),ISERROR($R2),ISERROR($S2),ISERROR($T2),ISERROR($X2),ISERROR($Y2),ISERROR($Z2)),1,0) -> 0 | AH2: =IF($AF2>0,$A2&" ("&$AV2&")","") | AI2: =IFERROR("Yes","Yes") -> Yes | AJ2: =IF(IFERROR(NOT(OR($K2="",$K2="Yes",$K2="Partial",$K2="No",$K2="N/A")),TRUE()),1,0) -> 0 | AK2: =IF(OR(IFERROR(IF($G2="",AND($I2="Yes",$K2<>""),IF(ISNUMBER($G2),OR($G2<1,$G2>5,$G2<>INT($G2)),TRUE())),TRUE()),IFERROR(IF($H2="",AND($I2="Yes",$K2<>""),IF(ISNUMBER($H2),OR($H2<1,$H2>5,$H2<>INT($H2)),TRUE())),TRUE())),1,0) -> 0 | AL2: =IF(IFERROR(NOT(OR($S2="",$S2="Open",$S2="In progress",$S2="Remediated",$S2="Accepted Risk",$S2="Not applicable")),TRUE()),1,0) -> 0 | AM2: =IF(OR(IFERROR(IF($S2="Accepted Risk",OR($X2="",$Y2="",$Z2=""),FALSE()),TRUE()),IF(IFERROR($Z2<>"",FALSE()),NOT(IFERROR(AND(ISNUMBER($Z2),$Z2>=DATE(2020,1,1),$Z2<=DATE(2100,12,31)),FALSE())),ISERROR($Z2))),1,0) -> 0 | AN2: =IF(IFERROR(AND($I2="Yes",$K2="N/A"),FALSE()),1,0) -> 0 | AO2: =IF(IFERROR(IF($J2<>"",$T2="",FALSE()),TRUE()),1,0) -> 0 | AP2: =IF(IFERROR(IF($I2="Yes",IF(OR($K2="Yes",$K2="Partial"),IF(ISERROR($O2),TRUE(),$O2=""),FALSE()),FALSE()),FALSE()),1,0) -> 0 | AQ2: =IF(OR($AF2>0,$AG2>0,$AJ2>0,$AK2>0,$AL2>0,$AM2>0,$AN2>0,$AO2>0),1,0) -> 0 | AR2: =IF(IFERROR(AND($I2="Yes",OR($K2="Yes",$K2="Partial",$K2="No")),FALSE()),1,0) -> 0 | AS2: =IFERROR(IF($AR2=1,$F2*$L2,0),0) -> 0 | AT2: =IFERROR(IF($AR2=1,$F2,0),0) -> 0 | AU2: =_xlfn.TEXTJOIN(", ",TRUE(),IF(ISERROR($E2),"E2",""),IF(ISERROR($G2),"G2",""),IF(ISERROR($H2),"H2",""),IF(ISERROR($J2),"J2",""),IF(ISERROR($K2),"K2",""),IF(ISERROR($O2),"O2",""),IF(ISERROR($P2),"P2",""),IF(ISERROR($Q2),"Q2",""),IF(ISERROR($R2),"R2",""),IF(ISERROR($S2),"S2",""),IF(ISERROR($T2),"T2",""),IF(ISERROR($X2),"X2",""),IF(ISERROR($Y2),"Y2",""),IF(ISERROR($Z2),"Z2","")) | AV2: =_xlfn.TEXTJOIN("; ",TRUE(),IF(IFERROR(NOT(OR($J2="",$J2="Yes",$J2="No")),TRUE()),"Invalid override value (J)",""),IF(IFERROR(IF($E2="",$I2="Yes",NOT(OR($E2="Blocker",$E2="Major",$E2="Moderate",$E2="Minor"))),TRUE()),"Invalid or missing criticality (E)",""),IF(IFERROR(IF($J2<>"",$T2="",FALSE()),TRUE()),"Override rationale missing / invalid (T)",""),IF(IFERROR(IF(AND($A2="2.7",$I2="Yes",p_confidential="Yes"),$E2<>"Blocker",FALSE()),TRUE()),"2.7 must be Blocker when S4 = Yes",""),IF(IFERROR(IF(AND($A2="5.8",$I2="Yes"),OR($E2="Moderate",$E2="Minor"),FALSE()),TRUE()),"5.8 should be at least Major",""),IF(IF(IFERROR(AND($J2="No",$AI2="Yes",OR($AD2="Blocker",AND($A2="2.7",p_confidential="Yes"))),FALSE()),NOT(AND(IFERROR($X2<>"",FALSE()),IFERROR($Y2<>"",FALSE()),IFERROR(AND(ISNUMBER($Z2),$Z2>=DATE(2020,1,1),$Z2<=DATE(2100,12,31)),FALSE()))),FALSE()),"Blocker de-scope review missing / invalid (X-Z)",""),IF(IF(IFERROR(IF(OR($E2="Blocker",$E2="Major",$E2="Moderate",$E2="Minor"),$F2<IF($AD2="Blocker",Lookups!$B$8,IF($AD2="Major",Lookups!$B$9,IF($AD2="Moderate",Lookups!$B$10,Lookups!$B$11))),FALSE()),FALSE()),NOT(AND(IFERROR($T2<>"",FALSE()),IFERROR($Y2<>"",FALSE()),IF(IFERROR($Z2<>"",FALSE()),IFERROR(AND(ISNUMBER($Z2),$Z2>=DATE(2020,1,1),$Z2<=DATE(2100,12,31)),FALSE()),NOT(ISERROR($Z2))))),FALSE()),"Criticality below baseline: review missing / invalid (T,Y,Z)","")) | AW2: =_xlfn.TEXTJOIN("; ",TRUE(),IF($AJ2>0,"Invalid response value (K)",""),IF($AK2>0,"Likelihood/Impact missing or not integer 1-5 (G,H)",""),IF($AL2>0,"Invalid status value (S)",""),IF($AM2>0,_xlfn.TEXTJOIN("; ",TRUE(),IF(IFERROR(AND($S2="Accepted Risk",$X2=""),FALSE()),"Exemption reference (X) missing",""),IF(IFERROR(AND($S2="Accepted Risk",$Y2=""),FALSE()),"Exemption approver (Y) missing",""),IF(IFERROR(AND($S2="Accepted Risk",$Z2=""),FALSE()),"Exemption date (Z) missing",""),IF(ISERROR($Z2),"Exemption date (Z) invalid - error value",IF(IFERROR(AND($Z2<>"",NOT(AND(ISNUMBER($Z2),$Z2>=DATE(2020,1,1),$Z2<=DATE(2100,12,31)))),FALSE()),"Exemption date (Z) invalid - enter a real date","")),IF(OR(ISERROR($S2),ISERROR($X2),ISERROR($Y2)),"Exemption inputs contain an error value (S,X,Y)","")),""),IF($AG2>0,"Input/calculation fault at "&$AU2,""),IF($AN2>0,"N/A on applicable row",""))
A3: 1.2 | B3: Use Case & Data | C3: Auto: always | D3: Data classification is defined, including personal, confidential, regulated, and export-controlled data. | E3: Blocker | F3: =IFERROR(IF($E3="Blocker",Lookups!$B$8,IF($E3="Major",Lookups!$B$9,IF($E3="Moderate",Lookups!$B$10,IF($E3="Minor",Lookups!$B$11,0)))),0) -> 5 | G3: 4 | H3: 5 | I3: =IFERROR(IF(OR($J3="Yes",$J3="No"),$J3,"Yes"),"Yes") -> Yes | L3: =IFERROR(IF(OR($I3="No",$K3="N/A"),"",IF($K3="Yes",1,IF($K3="Partial",0.5,IF($K3="No",0,"")))),"") | M3: =IFERROR(IF(OR($I3="No",$K3="N/A"),"",$F3*IF(OR($G3="",NOT(ISNUMBER($G3))),3,$G3)*IF(OR($H3="",NOT(ISNUMBER($H3))),3,$H3)*IF($K3="",1,1-$L3)),"") -> 100 | N3: =IFERROR(IF(OR($I3="No",$K3="N/A",$K3=""),"",IF(AND(IFERROR(AND($S3="Accepted Risk",$AM3=0),FALSE()),OR(AND($E3="Blocker",OR($K3="No",$K3="Partial")),AND($E3="Major",$K3="No"))),IF(AND($E3="Blocker",$K3="No"),"BLOCK",IF(AND($E3="Blocker",$K3="Partial"),IF(p_stage="Pilot / PoC","ESCALATE","BLOCK"),IF(AND($E3="Major",$K3="No"),"ESCALATE","")))&" (exempted)",IF(AND($E3="Blocker",$K3="No"),"BLOCK",IF(AND($E3="Blocker",$K3="Partial"),IF(p_stage="Pilot / PoC","ESCALATE","BLOCK"),IF(AND($E3="Major",$K3="No"),"ESCALATE",""))))),"") | U3: =_xlfn.TEXTJOIN("; ",TRUE(),$AV3,$AW3,IF($AP3>0,"Evidence missing or unusable","")) | W3: Good: classification scheme (personal / confidential / regulated / export-controlled) applied to all LLM inputs, outputs, prompts, logs, and retrieval corpora. Evidence: policy + data inventory. Partial: scheme exists but not applied to LLM data flows. Advisory map (partial): AI Act Art. 10. | AA3: =IF($AN3>0,$A3,"") | AB3: =IF($AO3>0,$A3,"") | AC3: =IF($AQ3>0,$A3&" ("&$U3&")","") | AD3: Blocker | AF3: =IF(OR(IFERROR(NOT(OR($J3="",$J3="Yes",$J3="No")),TRUE()),IFERROR(IF($E3="",$I3="Yes",NOT(OR($E3="Blocker",$E3="Major",$E3="Moderate",$E3="Minor"))),TRUE()),IFERROR(IF($J3<>"",$T3="",FALSE()),TRUE()),IFERROR(IF(AND($A3="2.7",$I3="Yes",p_confidential="Yes"),$E3<>"Blocker",FALSE()),TRUE()),IFERROR(IF(AND($A3="5.8",$I3="Yes"),OR($E3="Moderate",$E3="Minor"),FALSE()),TRUE()),IF(IFERROR(AND($J3="No",$AI3="Yes",OR($AD3="Blocker",AND($A3="2.7",p_confidential="Yes"))),FALSE()),NOT(AND(IFERROR($X3<>"",FALSE()),IFERROR($Y3<>"",FALSE()),IFERROR(AND(ISNUMBER($Z3),$Z3>=DATE(2020,1,1),$Z3<=DATE(2100,12,31)),FALSE()))),FALSE()),IF(IFERROR(IF(OR($E3="Blocker",$E3="Major",$E3="Moderate",$E3="Minor"),$F3<IF($AD3="Blocker",Lookups!$B$8,IF($AD3="Major",Lookups!$B$9,IF($AD3="Moderate",Lookups!$B$10,Lookups!$B$11))),FALSE()),FALSE()),NOT(AND(IFERROR($T3<>"",FALSE()),IFERROR($Y3<>"",FALSE()),IF(IFERROR($Z3<>"",FALSE()),IFERROR(AND(ISNUMBER($Z3),$Z3>=DATE(2020,1,1),$Z3<=DATE(2100,12,31)),FALSE()),NOT(ISERROR($Z3))))),FALSE())),1,0) -> 0 | AG3: =IF(OR(ISERROR($E3),ISERROR($G3),ISERROR($H3),ISERROR($J3),ISERROR($K3),ISERROR($O3),ISERROR($P3),ISERROR($Q3),ISERROR($R3),ISERROR($S3),ISERROR($T3),ISERROR($X3),ISERROR($Y3),ISERROR($Z3)),1,0) -> 0 | AH3: =IF($AF3>0,$A3&" ("&$AV3&")","") | AI3: =IFERROR("Yes","Yes") -> Yes | AJ3: =IF(IFERROR(NOT(OR($K3="",$K3="Yes",$K3="Partial",$K3="No",$K3="N/A")),TRUE()),1,0) -> 0 | AK3: =IF(OR(IFERROR(IF($G3="",AND($I3="Yes",$K3<>""),IF(ISNUMBER($G3),OR($G3<1,$G3>5,$G3<>INT($G3)),TRUE())),TRUE()),IFERROR(IF($H3="",AND($I3="Yes",$K3<>""),IF(ISNUMBER($H3),OR($H3<1,$H3>5,$H3<>INT($H3)),TRUE())),TRUE())),1,0) -> 0 | AL3: =IF(IFERROR(NOT(OR($S3="",$S3="Open",$S3="In progress",$S3="Remediated",$S3="Accepted Risk",$S3="Not applicable")),TRUE()),1,0) -> 0 | AM3: =IF(OR(IFERROR(IF($S3="Accepted Risk",OR($X3="",$Y3="",$Z3=""),FALSE()),TRUE()),IF(IFERROR($Z3<>"",FALSE()),NOT(IFERROR(AND(ISNUMBER($Z3),$Z3>=DATE(2020,1,1),$Z3<=DATE(2100,12,31)),FALSE())),ISERROR($Z3))),1,0) -> 0 | AN3: =IF(IFERROR(AND($I3="Yes",$K3="N/A"),FALSE()),1,0) -> 0 | AO3: =IF(IFERROR(IF($J3<>"",$T3="",FALSE()),TRUE()),1,0) -> 0 | AP3: =IF(IFERROR(IF($I3="Yes",IF(OR($K3="Yes",$K3="Partial"),IF(ISERROR($O3),TRUE(),$O3=""),FALSE()),FALSE()),FALSE()),1,0) -> 0 | AQ3: =IF(OR($AF3>0,$AG3>0,$AJ3>0,$AK3>0,$AL3>0,$AM3>0,$AN3>0,$AO3>0),1,0) -> 0 | AR3: =IF(IFERROR(AND($I3="Yes",OR($K3="Yes",$K3="Partial",$K3="No")),FALSE()),1,0) -> 0 | AS3: =IFERROR(IF($AR3=1,$F3*$L3,0),0) -> 0 | AT3: =IFERROR(IF($AR3=1,$F3,0),0) -> 0 | AU3: =_xlfn.TEXTJOIN(", ",TRUE(),IF(ISERROR($E3),"E3",""),IF(ISERROR($G3),"G3",""),IF(ISERROR($H3),"H3",""),IF(ISERROR($J3),"J3",""),IF(ISERROR($K3),"K3",""),IF(ISERROR($O3),"O3",""),IF(ISERROR($P3),"P3",""),IF(ISERROR($Q3),"Q3",""),IF(ISERROR($R3),"R3",""),IF(ISERROR($S3),"S3",""),IF(ISERROR($T3),"T3",""),IF(ISERROR($X3),"X3",""),IF(ISERROR($Y3),"Y3",""),IF(ISERROR($Z3),"Z3","")) | AV3: =_xlfn.TEXTJOIN("; ",TRUE(),IF(IFERROR(NOT(OR($J3="",$J3="Yes",$J3="No")),TRUE()),"Invalid override value (J)",""),IF(IFERROR(IF($E3="",$I3="Yes",NOT(OR($E3="Blocker",$E3="Major",$E3="Moderate",$E3="Minor"))),TRUE()),"Invalid or missing criticality (E)",""),IF(IFERROR(IF($J3<>"",$T3="",FALSE()),TRUE()),"Override rationale missing / invalid (T)",""),IF(IFERROR(IF(AND($A3="2.7",$I3="Yes",p_confidential="Yes"),$E3<>"Blocker",FALSE()),TRUE()),"2.7 must be Blocker when S4 = Yes",""),IF(IFERROR(IF(AND($A3="5.8",$I3="Yes"),OR($E3="Moderate",$E3="Minor"),FALSE()),TRUE()),"5.8 should be at least Major",""),IF(IF(IFERROR(AND($J3="No",$AI3="Yes",OR($AD3="Blocker",AND($A3="2.7",p_confidential="Yes"))),FALSE()),NOT(AND(IFERROR($X3<>"",FALSE()),IFERROR($Y3<>"",FALSE()),IFERROR(AND(ISNUMBER($Z3),$Z3>=DATE(2020,1,1),$Z3<=DATE(2100,12,31)),FALSE()))),FALSE()),"Blocker de-scope review missing / invalid (X-Z)",""),IF(IF(IFERROR(IF(OR($E3="Blocker",$E3="Major",$E3="Moderate",$E3="Minor"),$F3<IF($AD3="Blocker",Lookups!$B$8,IF($AD3="Major",Lookups!$B$9,IF($AD3="Moderate",Lookups!$B$10,Lookups!$B$11))),FALSE()),FALSE()),NOT(AND(IFERROR($T3<>"",FALSE()),IFERROR($Y3<>"",FALSE()),IF(IFERROR($Z3<>"",FALSE()),IFERROR(AND(ISNUMBER($Z3),$Z3>=DATE(2020,1,1),$Z3<=DATE(2100,12,31)),FALSE()),NOT(ISERROR($Z3))))),FALSE()),"Criticality below baseline: review missing / invalid (T,Y,Z)","")) | AW3: =_xlfn.TEXTJOIN("; ",TRUE(),IF($AJ3>0,"Invalid response value (K)",""),IF($AK3>0,"Likelihood/Impact missing or not integer 1-5 (G,H)",""),IF($AL3>0,"Invalid status value (S)",""),IF($AM3>0,_xlfn.TEXTJOIN("; ",TRUE(),IF(IFERROR(AND($S3="Accepted Risk",$X3=""),FALSE()),"Exemption reference (X) missing",""),IF(IFERROR(AND($S3="Accepted Risk",$Y3=""),FALSE()),"Exemption approver (Y) missing",""),IF(IFERROR(AND($S3="Accepted Risk",$Z3=""),FALSE()),"Exemption date (Z) missing",""),IF(ISERROR($Z3),"Exemption date (Z) invalid - error value",IF(IFERROR(AND($Z3<>"",NOT(AND(ISNUMBER($Z3),$Z3>=DATE(2020,1,1),$Z3<=DATE(2100,12,31)))),FALSE()),"Exemption date (Z) invalid - enter a real date","")),IF(OR(ISERROR($S3),ISERROR($X3),ISERROR($Y3)),"Exemption inputs contain an error value (S,X,Y)","")),""),IF($AG3>0,"Input/calculation fault at "&$AU3,""),IF($AN3>0,"N/A on applicable row",""))
A4: 1.3 | B4: Use Case & Data | C4: Auto: unless S5 = No | D4: AI Act classification is completed: prohibited, high-risk, GPAI dependency, deployer/provider role, and transparency obligations. | E4: Blocker | F4: =IFERROR(IF($E4="Blocker",Lookups!$B$8,IF($E4="Major",Lookups!$B$9,IF($E4="Moderate",Lookups!$B$10,IF($E4="Minor",Lookups!$B$11,0)))),0) -> 5 | G4: 3 | H4: 5 | I4: =IFERROR(IF(OR($J4="Yes",$J4="No"),$J4,IF(p_eu="No","No","Yes")),"Yes") -> Yes | L4: =IFERROR(IF(OR($I4="No",$K4="N/A"),"",IF($K4="Yes",1,IF($K4="Partial",0.5,IF($K4="No",0,"")))),"") | M4: =IFERROR(IF(OR($I4="No",$K4="N/A"),"",$F4*IF(OR($G4="",NOT(ISNUMBER($G4))),3,$G4)*IF(OR($H4="",NOT(ISNUMBER($H4))),3,$H4)*IF($K4="",1,1-$L4)),"") -> 75 | N4: =IFERROR(IF(OR($I4="No",$K4="N/A",$K4=""),"",IF(AND(IFERROR(AND($S4="Accepted Risk",$AM4=0),FALSE()),OR(AND($E4="Blocker",OR($K4="No",$K4="Partial")),AND($E4="Major",$K4="No"))),IF(AND($E4="Blocker",$K4="No"),"BLOCK",IF(AND($E4="Blocker",$K4="Partial"),IF(p_stage="Pilot / PoC","ESCALATE","BLOCK"),IF(AND($E4="Major",$K4="No"),"ESCALATE","")))&" (exempted)",IF(AND($E4="Blocker",$K4="No"),"BLOCK",IF(AND($E4="Blocker",$K4="Partial"),IF(p_stage="Pilot / PoC","ESCALATE","BLOCK"),IF(AND($E4="Major",$K4="No"),"ESCALATE",""))))),"") | U4: =_xlfn.TEXTJOIN("; ",TRUE(),$AV4,$AW4,IF($AP4>0,"Evidence missing or unusable","")) | W4: Good: documented AI Act classification with rationale: prohibited-practices screen, Annex III high-risk check, GPAI dependency, deployer/provider role, transparency duties. Evidence: legal assessment memo. Partial: classification done, rationale or role unclear. Advisory map (partial): AI Act Art. 5, 6, Annex III. | AA4: =IF($AN4>0,$A4,"") | AB4: =IF($AO4>0,$A4,"") | AC4: =IF($AQ4>0,$A4&" ("&$U4&")","") | AD4: Blocker | AF4: =IF(OR(IFERROR(NOT(OR($J4="",$J4="Yes",$J4="No")),TRUE()),IFERROR(IF($E4="",$I4="Yes",NOT(OR($E4="Blocker",$E4="Major",$E4="Moderate",$E4="Minor"))),TRUE()),IFERROR(IF($J4<>"",$T4="",FALSE()),TRUE()),IFERROR(IF(AND($A4="2.7",$I4="Yes",p_confidential="Yes"),$E4<>"Blocker",FALSE()),TRUE()),IFERROR(IF(AND($A4="5.8",$I4="Yes"),OR($E4="Moderate",$E4="Minor"),FALSE()),TRUE()),IF(IFERROR(AND($J4="No",$AI4="Yes",OR($AD4="Blocker",AND($A4="2.7",p_confidential="Yes"))),FALSE()),NOT(AND(IFERROR($X4<>"",FALSE()),IFERROR($Y4<>"",FALSE()),IFERROR(AND(ISNUMBER($Z4),$Z4>=DATE(2020,1,1),$Z4<=DATE(2100,12,31)),FALSE()))),FALSE()),IF(IFERROR(IF(OR($E4="Blocker",$E4="Major",$E4="Moderate",$E4="Minor"),$F4<IF($AD4="Blocker",Lookups!$B$8,IF($AD4="Major",Lookups!$B$9,IF($AD4="Moderate",Lookups!$B$10,Lookups!$B$11))),FALSE()),FALSE()),NOT(AND(IFERROR($T4<>"",FALSE()),IFERROR($Y4<>"",FALSE()),IF(IFERROR($Z4<>"",FALSE()),IFERROR(AND(ISNUMBER($Z4),$Z4>=DATE(2020,1,1),$Z4<=DATE(2100,12,31)),FALSE()),NOT(ISERROR($Z4))))),FALSE())),1,0) -> 0 | AG4: =IF(OR(ISERROR($E4),ISERROR($G4),ISERROR($H4),ISERROR($J4),ISERROR($K4),ISERROR($O4),ISERROR($P4),ISERROR($Q4),ISERROR($R4),ISERROR($S4),ISERROR($T4),ISERROR($X4),ISERROR($Y4),ISERROR($Z4)),1,0) -> 0 | AH4: =IF($AF4>0,$A4&" ("&$AV4&")","") | AI4: =IFERROR(IF(p_eu="No","No","Yes"),"Yes") -> Yes | AJ4: =IF(IFERROR(NOT(OR($K4="",$K4="Yes",$K4="Partial",$K4="No",$K4="N/A")),TRUE()),1,0) -> 0 | AK4: =IF(OR(IFERROR(IF($G4="",AND($I4="Yes",$K4<>""),IF(ISNUMBER($G4),OR($G4<1,$G4>5,$G4<>INT($G4)),TRUE())),TRUE()),IFERROR(IF($H4="",AND($I4="Yes",$K4<>""),IF(ISNUMBER($H4),OR($H4<1,$H4>5,$H4<>INT($H4)),TRUE())),TRUE())),1,0) -> 0 | AL4: =IF(IFERROR(NOT(OR($S4="",$S4="Open",$S4="In progress",$S4="Remediated",$S4="Accepted Risk",$S4="Not applicable")),TRUE()),1,0) -> 0 | AM4: =IF(OR(IFERROR(IF($S4="Accepted Risk",OR($X4="",$Y4="",$Z4=""),FALSE()),TRUE()),IF(IFERROR($Z4<>"",FALSE()),NOT(IFERROR(AND(ISNUMBER($Z4),$Z4>=DATE(2020,1,1),$Z4<=DATE(2100,12,31)),FALSE())),ISERROR($Z4))),1,0) -> 0 | AN4: =IF(IFERROR(AND($I4="Yes",$K4="N/A"),FALSE()),1,0) -> 0 | AO4: =IF(IFERROR(IF($J4<>"",$T4="",FALSE()),TRUE()),1,0) -> 0 | AP4: =IF(IFERROR(IF($I4="Yes",IF(OR($K4="Yes",$K4="Partial"),IF(ISERROR($O4),TRUE(),$O4=""),FALSE()),FALSE()),FALSE()),1,0) -> 0 | AQ4: =IF(OR($AF4>0,$AG4>0,$AJ4>0,$AK4>0,$AL4>0,$AM4>0,$AN4>0,$AO4>0),1,0) -> 0 | AR4: =IF(IFERROR(AND($I4="Yes",OR($K4="Yes",$K4="Partial",$K4="No")),FALSE()),1,0) -> 0 | AS4: =IFERROR(IF($AR4=1,$F4*$L4,0),0) -> 0 | AT4: =IFERROR(IF($AR4=1,$F4,0),0) -> 0 | AU4: =_xlfn.TEXTJOIN(", ",TRUE(),IF(ISERROR($E4),"E4",""),IF(ISERROR($G4),"G4",""),IF(ISERROR($H4),"H4",""),IF(ISERROR($J4),"J4",""),IF(ISERROR($K4),"K4",""),IF(ISERROR($O4),"O4",""),IF(ISERROR($P4),"P4",""),IF(ISERROR($Q4),"Q4",""),IF(ISERROR($R4),"R4",""),IF(ISERROR($S4),"S4",""),IF(ISERROR($T4),"T4",""),IF(ISERROR($X4),"X4",""),IF(ISERROR($Y4),"Y4",""),IF(ISERROR($Z4),"Z4","")) | AV4: =_xlfn.TEXTJOIN("; ",TRUE(),IF(IFERROR(NOT(OR($J4="",$J4="Yes",$J4="No")),TRUE()),"Invalid override value (J)",""),IF(IFERROR(IF($E4="",$I4="Yes",NOT(OR($E4="Blocker",$E4="Major",$E4="Moderate",$E4="Minor"))),TRUE()),"Invalid or missing criticality (E)",""),IF(IFERROR(IF($J4<>"",$T4="",FALSE()),TRUE()),"Override rationale missing / invalid (T)",""),IF(IFERROR(IF(AND($A4="2.7",$I4="Yes",p_confidential="Yes"),$E4<>"Blocker",FALSE()),TRUE()),"2.7 must be Blocker when S4 = Yes",""),IF(IFERROR(IF(AND($A4="5.8",$I4="Yes"),OR($E4="Moderate",$E4="Minor"),FALSE()),TRUE()),"5.8 should be at least Major",""),IF(IF(IFERROR(AND($J4="No",$AI4="Yes",OR($AD4="Blocker",AND($A4="2.7",p_confidential="Yes"))),FALSE()),NOT(AND(IFERROR($X4<>"",FALSE()),IFERROR($Y4<>"",FALSE()),IFERROR(AND(ISNUMBER($Z4),$Z4>=DATE(2020,1,1),$Z4<=DATE(2100,12,31)),FALSE()))),FALSE()),"Blocker de-scope review missing / invalid (X-Z)",""),IF(IF(IFERROR(IF(OR($E4="Blocker",$E4="Major",$E4="Moderate",$E4="Minor"),$F4<IF($AD4="Blocker",Lookups!$B$8,IF($AD4="Major",Lookups!$B$9,IF($AD4="Moderate",Lookups!$B$10,Lookups!$B$11))),FALSE()),FALSE()),NOT(AND(IFERROR($T4<>"",FALSE()),IFERROR($Y4<>"",FALSE()),IF(IFERROR($Z4<>"",FALSE()),IFERROR(AND(ISNUMBER($Z4),$Z4>=DATE(2020,1,1),$Z4<=DATE(2100,12,31)),FALSE()),NOT(ISERROR($Z4))))),FALSE()),"Criticality below baseline: review missing / invalid (T,Y,Z)","")) | AW4: =_xlfn.TEXTJOIN("; ",TRUE(),IF($AJ4>0,"Invalid response value (K)",""),IF($AK4>0,"Likelihood/Impact missing or not integer 1-5 (G,H)",""),IF($AL4>0,"Invalid status value (S)",""),IF($AM4>0,_xlfn.TEXTJOIN("; ",TRUE(),IF(IFERROR(AND($S4="Accepted Risk",$X4=""),FALSE()),"Exemption reference (X) missing",""),IF(IFERROR(AND($S4="Accepted Risk",$Y4=""),FALSE()),"Exemption approver (Y) missing",""),IF(IFERROR(AND($S4="Accepted Risk",$Z4=""),FALSE()),"Exemption date (Z) missing",""),IF(ISERROR($Z4),"Exemption date (Z) invalid - error value",IF(IFERROR(AND($Z4<>"",NOT(AND(ISNUMBER($Z4),$Z4>=DATE(2020,1,1),$Z4<=DATE(2100,12,31)))),FALSE()),"Exemption date (Z) invalid - enter a real date","")),IF(OR(ISERROR($S4),ISERROR($X4),ISERROR($Y4)),"Exemption inputs contain an error value (S,X,Y)","")),""),IF($AG4>0,"Input/calculation fault at "&$AU4,""),IF($AN4>0,"N/A on applicable row",""))
A5: 1.4 | B5: Use Case & Data | C5: Auto: unless S8 = No and S18 = Assist | D5: Human oversight, accountability, escalation, and override are defined for consequential outputs. | E5: Major | F5: =IFERROR(IF($E5="Blocker",Lookups!$B$8,IF($E5="Major",Lookups!$B$9,IF($E5="Moderate",Lookups!$B$10,IF($E5="Minor",Lookups!$B$11,0)))),0) -> 4 | G5: 3 | H5: 5 | I5: =IFERROR(IF(OR($J5="Yes",$J5="No"),$J5,IF(AND(p_decisions="No",p_role="Assist (informs a human)"),"No","Yes")),"Yes") -> Yes | L5: =IFERROR(IF(OR($I5="No",$K5="N/A"),"",IF($K5="Yes",1,IF($K5="Partial",0.5,IF($K5="No",0,"")))),"") | M5: =IFERROR(IF(OR($I5="No",$K5="N/A"),"",$F5*IF(OR($G5="",NOT(ISNUMBER($G5))),3,$G5)*IF(OR($H5="",NOT(ISNUMBER($H5))),3,$H5)*IF($K5="",1,1-$L5)),"") -> 60 | N5: =IFERROR(IF(OR($I5="No",$K5="N/A",$K5=""),"",IF(AND(IFERROR(AND($S5="Accepted Risk",$AM5=0),FALSE()),OR(AND($E5="Blocker",OR($K5="No",$K5="Partial")),AND($E5="Major",$K5="No"))),IF(AND($E5="Blocker",$K5="No"),"BLOCK",IF(AND($E5="Blocker",$K5="Partial"),IF(p_stage="Pilot / PoC","ESCALATE","BLOCK"),IF(AND($E5="Major",$K5="No"),"ESCALATE","")))&" (exempted)",IF(AND($E5="Blocker",$K5="No"),"BLOCK",IF(AND($E5="Blocker",$K5="Partial"),IF(p_stage="Pilot / PoC","ESCALATE","BLOCK"),IF(AND($E5="Major",$K5="No"),"ESCALATE",""))))),"") | U5: =_xlfn.TEXTJOIN("; ",TRUE(),$AV5,$AW5,IF($AP5>0,"Evidence missing or unusable","")) | W5: Good: named human owner for consequential outputs, escalation path, tested ability to override or disable. Evidence: operating procedure, RACI, override test. Partial: oversight defined but override untested. Advisory map (partial): AI Act Art. 14. | AA5: =IF($AN5>0,$A5,"") | AB5: =IF($AO5>0,$A5,"") | AC5: =IF($AQ5>0,$A5&" ("&$U5&")","") | AD5: Major | AF5: =IF(OR(IFERROR(NOT(OR($J5="",$J5="Yes",$J5="No")),TRUE()),IFERROR(IF($E5="",$I5="Yes",NOT(OR($E5="Blocker",$E5="Major",$E5="Moderate",$E5="Minor"))),TRUE()),IFERROR(IF($J5<>"",$T5="",FALSE()),TRUE()),IFERROR(IF(AND($A5="2.7",$I5="Yes",p_confidential="Yes"),$E5<>"Blocker",FALSE()),TRUE()),IFERROR(IF(AND($A5="5.8",$I5="Yes"),OR($E5="Moderate",$E5="Minor"),FALSE()),TRUE()),IF(IFERROR(AND($J5="No",$AI5="Yes",OR($AD5="Blocker",AND($A5="2.7",p_confidential="Yes"))),FALSE()),NOT(AND(IFERROR($X5<>"",FALSE()),IFERROR($Y5<>"",FALSE()),IFERROR(AND(ISNUMBER($Z5),$Z5>=DATE(2020,1,1),$Z5<=DATE(2100,12,31)),FALSE()))),FALSE()),IF(IFERROR(IF(OR($E5="Blocker",$E5="Major",$E5="Moderate",$E5="Minor"),$F5<IF($AD5="Blocker",Lookups!$B$8,IF($AD5="Major",Lookups!$B$9,IF($AD5="Moderate",Lookups!$B$10,Lookups!$B$11))),FALSE()),FALSE()),NOT(AND(IFERROR($T5<>"",FALSE()),IFERROR($Y5<>"",FALSE()),IF(IFERROR($Z5<>"",FALSE()),IFERROR(AND(ISNUMBER($Z5),$Z5>=DATE(2020,1,1),$Z5<=DATE(2100,12,31)),FALSE()),NOT(ISERROR($Z5))))),FALSE())),1,0) -> 0 | AG5: =IF(OR(ISERROR($E5),ISERROR($G5),ISERROR($H5),ISERROR($J5),ISERROR($K5),ISERROR($O5),ISERROR($P5),ISERROR($Q5),ISERROR($R5),ISERROR($S5),ISERROR($T5),ISERROR($X5),ISERROR($Y5),ISERROR($Z5)),1,0) -> 0 | AH5: =IF($AF5>0,$A5&" ("&$AV5&")","") | AI5: =IFERROR(IF(AND(p_decisions="No",p_role="Assist (informs a human)"),"No","Yes"),"Yes") -> Yes | AJ5: =IF(IFERROR(NOT(OR($K5="",$K5="Yes",$K5="Partial",$K5="No",$K5="N/A")),TRUE()),1,0) -> 0 | AK5: =IF(OR(IFERROR(IF($G5="",AND($I5="Yes",$K5<>""),IF(ISNUMBER($G5),OR($G5<1,$G5>5,$G5<>INT($G5)),TRUE())),TRUE()),IFERROR(IF($H5="",AND($I5="Yes",$K5<>""),IF(ISNUMBER($H5),OR($H5<1,$H5>5,$H5<>INT($H5)),TRUE())),TRUE())),1,0) -> 0 | AL5: =IF(IFERROR(NOT(OR($S5="",$S5="Open",$S5="In progress",$S5="Remediated",$S5="Accepted Risk",$S5="Not applicable")),TRUE()),1,0) -> 0 | AM5: =IF(OR(IFERROR(IF($S5="Accepted Risk",OR($X5="",$Y5="",$Z5=""),FALSE()),TRUE()),IF(IFERROR($Z5<>"",FALSE()),NOT(IFERROR(AND(ISNUMBER($Z5),$Z5>=DATE(2020,1,1),$Z5<=DATE(2100,12,31)),FALSE())),ISERROR($Z5))),1,0) -> 0 | AN5: =IF(IFERROR(AND($I5="Yes",$K5="N/A"),FALSE()),1,0) -> 0 | AO5: =IF(IFERROR(IF($J5<>"",$T5="",FALSE()),TRUE()),1,0) -> 0 | AP5: =IF(IFERROR(IF($I5="Yes",IF(OR($K5="Yes",$K5="Partial"),IF(ISERROR($O5),TRUE(),$O5=""),FALSE()),FALSE()),FALSE()),1,0) -> 0 | AQ5: =IF(OR($AF5>0,$AG5>0,$AJ5>0,$AK5>0,$AL5>0,$AM5>0,$AN5>0,$AO5>0),1,0) -> 0 | AR5: =IF(IFERROR(AND($I5="Yes",OR($K5="Yes",$K5="Partial",$K5="No")),FALSE()),1,0) -> 0 | AS5: =IFERROR(IF($AR5=1,$F5*$L5,0),0) -> 0 | AT5: =IFERROR(IF($AR5=1,$F5,0),0) -> 0 | AU5: =_xlfn.TEXTJOIN(", ",TRUE(),IF(ISERROR($E5),"E5",""),IF(ISERROR($G5),"G5",""),IF(ISERROR($H5),"H5",""),IF(ISERROR($J5),"J5",""),IF(ISERROR($K5),"K5",""),IF(ISERROR($O5),"O5",""),IF(ISERROR($P5),"P5",""),IF(ISERROR($Q5),"Q5",""),IF(ISERROR($R5),"R5",""),IF(ISERROR($S5),"S5",""),IF(ISERROR($T5),"T5",""),IF(ISERROR($X5),"X5",""),IF(ISERROR($Y5),"Y5",""),IF(ISERROR($Z5),"Z5","")) | AV5: =_xlfn.TEXTJOIN("; ",TRUE(),IF(IFERROR(NOT(OR($J5="",$J5="Yes",$J5="No")),TRUE()),"Invalid override value (J)",""),IF(IFERROR(IF($E5="",$I5="Yes",NOT(OR($E5="Blocker",$E5="Major",$E5="Moderate",$E5="Minor"))),TRUE()),"Invalid or missing criticality (E)",""),IF(IFERROR(IF($J5<>"",$T5="",FALSE()),TRUE()),"Override rationale missing / invalid (T)",""),IF(IFERROR(IF(AND($A5="2.7",$I5="Yes",p_confidential="Yes"),$E5<>"Blocker",FALSE()),TRUE()),"2.7 must be Blocker when S4 = Yes",""),IF(IFERROR(IF(AND($A5="5.8",$I5="Yes"),OR($E5="Moderate",$E5="Minor"),FALSE()),TRUE()),"5.8 should be at least Major",""),IF(IF(IFERROR(AND($J5="No",$AI5="Yes",OR($AD5="Blocker",AND($A5="2.7",p_confidential="Yes"))),FALSE()),NOT(AND(IFERROR($X5<>"",FALSE()),IFERROR($Y5<>"",FALSE()),IFERROR(AND(ISNUMBER($Z5),$Z5>=DATE(2020,1,1),$Z5<=DATE(2100,12,31)),FALSE()))),FALSE()),"Blocker de-scope review missing / invalid (X-Z)",""),IF(IF(IFERROR(IF(OR($E5="Blocker",$E5="Major",$E5="Moderate",$E5="Minor"),$F5<IF($AD5="Blocker",Lookups!$B$8,IF($AD5="Major",Lookups!$B$9,IF($AD5="Moderate",Lookups!$B$10,Lookups!$B$11))),FALSE()),FALSE()),NOT(AND(IFERROR($T5<>"",FALSE()),IFERROR($Y5<>"",FALSE()),IF(IFERROR($Z5<>"",FALSE()),IFERROR(AND(ISNUMBER($Z5),$Z5>=DATE(2020,1,1),$Z5<=DATE(2100,12,31)),FALSE()),NOT(ISERROR($Z5))))),FALSE()),"Criticality below baseline: review missing / invalid (T,Y,Z)","")) | AW5: =_xlfn.TEXTJOIN("; ",TRUE(),IF($AJ5>0,"Invalid response value (K)",""),IF($AK5>0,"Likelihood/Impact missing or not integer 1-5 (G,H)",""),IF($AL5>0,"Invalid status value (S)",""),IF($AM5>0,_xlfn.TEXTJOIN("; ",TRUE(),IF(IFERROR(AND($S5="Accepted Risk",$X5=""),FALSE()),"Exemption reference (X) missing",""),IF(IFERROR(AND($S5="Accepted Risk",$Y5=""),FALSE()),"Exemption approver (Y) missing",""),IF(IFERROR(AND($S5="Accepted Risk",$Z5=""),FALSE()),"Exemption date (Z) missing",""),IF(ISERROR($Z5),"Exemption date (Z) invalid - error value",IF(IFERROR(AND($Z5<>"",NOT(AND(ISNUMBER($Z5),$Z5>=DATE(2020,1,1),$Z5<=DATE(2100,12,31)))),FALSE()),"Exemption date (Z) invalid - enter a real date","")),IF(OR(ISERROR($S5),ISERROR($X5),ISERROR($Y5)),"Exemption inputs contain an error value (S,X,Y)","")),""),IF($AG5>0,"Input/calculation fault at "&$AU5,""),IF($AN5>0,"N/A on applicable row",""))
A6: 1.5 | B6: Use Case & Data | C6: Auto: unless S12 = None | D6: The system does not execute high-impact actions autonomously without policy, validation, and approval controls. | E6: Blocker | F6: =IFERROR(IF($E6="Blocker",Lookups!$B$8,IF($E6="Major",Lookups!$B$9,IF($E6="Moderate",Lookups!$B$10,IF($E6="Minor",Lookups!$B$11,0)))),0) -> 5 | G6: 3 | H6: 5 | I6: =IFERROR(IF(OR($J6="Yes",$J6="No"),$J6,IF(p_autonomy="None (chat or single completions)","No","Yes")),"Yes") -> Yes | L6: =IFERROR(IF(OR($I6="No",$K6="N/A"),"",IF($K6="Yes",1,IF($K6="Partial",0.5,IF($K6="No",0,"")))),"") | M6: =IFERROR(IF(OR($I6="No",$K6="N/A"),"",$F6*IF(OR($G6="",NOT(ISNUMBER($G6))),3,$G6)*IF(OR($H6="",NOT(ISNUMBER($H6))),3,$H6)*IF($K6="",1,1-$L6)),"") -> 75 | N6: =IFERROR(IF(OR($I6="No",$K6="N/A",$K6=""),"",IF(AND(IFERROR(AND($S6="Accepted Risk",$AM6=0),FALSE()),OR(AND($E6="Blocker",OR($K6="No",$K6="Partial")),AND($E6="Major",$K6="No"))),IF(AND($E6="Blocker",$K6="No"),"BLOCK",IF(AND($E6="Blocker",$K6="Partial"),IF(p_stage="Pilot / PoC","ESCALATE","BLOCK"),IF(AND($E6="Major",$K6="No"),"ESCALATE","")))&" (exempted)",IF(AND($E6="Blocker",$K6="No"),"BLOCK",IF(AND($E6="Blocker",$K6="Partial"),IF(p_stage="Pilot / PoC","ESCALATE","BLOCK"),IF(AND($E6="Major",$K6="No"),"ESCALATE",""))))),"") | U6: =_xlfn.TEXTJOIN("; ",TRUE(),$AV6,$AW6,IF($AP6>0,"Evidence missing or unusable","")) | V6: 4.6, 9.2, 9.4 — 1.5 is the policy-level autonomy gate; 4.6 runtime constraint/logging; 9.2 approval for high-impact actions; 9.4 tool allowlist/sandbox. | W6: Good: written policy of permitted autonomous actions, enforced technically (approval gates, validation, dry-run). Evidence: policy + enforcement config. Partial: policy exists, enforcement incomplete. Advisory map (partial): OWASP LLM06 Excessive Agency; OWASP Agentic ASI01. | AA6: =IF($AN6>0,$A6,"") | AB6: =IF($AO6>0,$A6,"") | AC6: =IF($AQ6>0,$A6&" ("&$U6&")","") | AD6: Blocker | AF6: =IF(OR(IFERROR(NOT(OR($J6="",$J6="Yes",$J6="No")),TRUE()),IFERROR(IF($E6="",$I6="Yes",NOT(OR($E6="Blocker",$E6="Major",$E6="Moderate",$E6="Minor"))),TRUE()),IFERROR(IF($J6<>"",$T6="",FALSE()),TRUE()),IFERROR(IF(AND($A6="2.7",$I6="Yes",p_confidential="Yes"),$E6<>"Blocker",FALSE()),TRUE()),IFERROR(IF(AND($A6="5.8",$I6="Yes"),OR($E6="Moderate",$E6="Minor"),FALSE()),TRUE()),IF(IFERROR(AND($J6="No",$AI6="Yes",OR($AD6="Blocker",AND($A6="2.7",p_confidential="Yes"))),FALSE()),NOT(AND(IFERROR($X6<>"",FALSE()),IFERROR($Y6<>"",FALSE()),IFERROR(AND(ISNUMBER($Z6),$Z6>=DATE(2020,1,1),$Z6<=DATE(2100,12,31)),FALSE()))),FALSE()),IF(IFERROR(IF(OR($E6="Blocker",$E6="Major",$E6="Moderate",$E6="Minor"),$F6<IF($AD6="Blocker",Lookups!$B$8,IF($AD6="Major",Lookups!$B$9,IF($AD6="Moderate",Lookups!$B$10,Lookups!$B$11))),FALSE()),FALSE()),NOT(AND(IFERROR($T6<>"",FALSE()),IFERROR($Y6<>"",FALSE()),IF(IFERROR($Z6<>"",FALSE()),IFERROR(AND(ISNUMBER($Z6),$Z6>=DATE(2020,1,1),$Z6<=DATE(2100,12,31)),FALSE()),NOT(ISERROR($Z6))))),FALSE())),1,0) -> 0 | AG6: =IF(OR(ISERROR($E6),ISERROR($G6),ISERROR($H6),ISERROR($J6),ISERROR($K6),ISERROR($O6),ISERROR($P6),ISERROR($Q6),ISERROR($R6),ISERROR($S6),ISERROR($T6),ISERROR($X6),ISERROR($Y6),ISERROR($Z6)),1,0) -> 0 | AH6: =IF($AF6>0,$A6&" ("&$AV6&")","") | AI6: =IFERROR(IF(p_autonomy="None (chat or single completions)","No","Yes"),"Yes") -> Yes | AJ6: =IF(IFERROR(NOT(OR($K6="",$K6="Yes",$K6="Partial",$K6="No",$K6="N/A")),TRUE()),1,0) -> 0 | AK6: =IF(OR(IFERROR(IF($G6="",AND($I6="Yes",$K6<>""),IF(ISNUMBER($G6),OR($G6<1,$G6>5,$G6<>INT($G6)),TRUE())),TRUE()),IFERROR(IF($H6="",AND($I6="Yes",$K6<>""),IF(ISNUMBER($H6),OR($H6<1,$H6>5,$H6<>INT($H6)),TRUE())),TRUE())),1,0) -> 0 | AL6: =IF(IFERROR(NOT(OR($S6="",$S6="Open",$S6="In progress",$S6="Remediated",$S6="Accepted Risk",$S6="Not applicable")),TRUE()),1,0) -> 0 | AM6: =IF(OR(IFERROR(IF($S6="Accepted Risk",OR($X6="",$Y6="",$Z6=""),FALSE()),TRUE()),IF(IFERROR($Z6<>"",FALSE()),NOT(IFERROR(AND(ISNUMBER($Z6),$Z6>=DATE(2020,1,1),$Z6<=DATE(2100,12,31)),FALSE())),ISERROR($Z6))),1,0) -> 0 | AN6: =IF(IFERROR(AND($I6="Yes",$K6="N/A"),FALSE()),1,0) -> 0 | AO6: =IF(IFERROR(IF($J6<>"",$T6="",FALSE()),TRUE()),1,0) -> 0 | AP6: =IF(IFERROR(IF($I6="Yes",IF(OR($K6="Yes",$K6="Partial"),IF(ISERROR($O6),TRUE(),$O6=""),FALSE()),FALSE()),FALSE()),1,0) -> 0 | AQ6: =IF(OR($AF6>0,$AG6>0,$AJ6>0,$AK6>0,$AL6>0,$AM6>0,$AN6>0,$AO6>0),1,0) -> 0 | AR6: =IF(IFERROR(AND($I6="Yes",OR($K6="Yes",$K6="Partial",$K6="No")),FALSE()),1,0) -> 0 | AS6: =IFERROR(IF($AR6=1,$F6*$L6,0),0) -> 0 | AT6: =IFERROR(IF($AR6=1,$F6,0),0) -> 0 | AU6: =_xlfn.TEXTJOIN(", ",TRUE(),IF(ISERROR($E6),"E6",""),IF(ISERROR($G6),"G6",""),IF(ISERROR($H6),"H6",""),IF(ISERROR($J6),"J6",""),IF(ISERROR($K6),"K6",""),IF(ISERROR($O6),"O6",""),IF(ISERROR($P6),"P6",""),IF(ISERROR($Q6),"Q6",""),IF(ISERROR($R6),"R6",""),IF(ISERROR($S6),"S6",""),IF(ISERROR($T6),"T6",""),IF(ISERROR($X6),"X6",""),IF(ISERROR($Y6),"Y6",""),IF(ISERROR($Z6),"Z6","")) | AV6: =_xlfn.TEXTJOIN("; ",TRUE(),IF(IFERROR(NOT(OR($J6="",$J6="Yes",$J6="No")),TRUE()),"Invalid override value (J)",""),IF(IFERROR(IF($E6="",$I6="Yes",NOT(OR($E6="Blocker",$E6="Major",$E6="Moderate",$E6="Minor"))),TRUE()),"Invalid or missing criticality (E)",""),IF(IFERROR(IF($J6<>"",$T6="",FALSE()),TRUE()),"Override rationale missing / invalid (T)",""),IF(IFERROR(IF(AND($A6="2.7",$I6="Yes",p_confidential="Yes"),$E6<>"Blocker",FALSE()),TRUE()),"2.7 must be Blocker when S4 = Yes",""),IF(IFERROR(IF(AND($A6="5.8",$I6="Yes"),OR($E6="Moderate",$E6="Minor"),FALSE()),TRUE()),"5.8 should be at least Major",""),IF(IF(IFERROR(AND($J6="No",$AI6="Yes",OR($AD6="Blocker",AND($A6="2.7",p_confidential="Yes"))),FALSE()),NOT(AND(IFERROR($X6<>"",FALSE()),IFERROR($Y6<>"",FALSE()),IFERROR(AND(ISNUMBER($Z6),$Z6>=DATE(2020,1,1),$Z6<=DATE(2100,12,31)),FALSE()))),FALSE()),"Blocker de-scope review missing / invalid (X-Z)",""),IF(IF(IFERROR(IF(OR($E6="Blocker",$E6="Major",$E6="Moderate",$E6="Minor"),$F6<IF($AD6="Blocker",Lookups!$B$8,IF($AD6="Major",Lookups!$B$9,IF($AD6="Moderate",Lookups!$B$10,Lookups!$B$11))),FALSE()),FALSE()),NOT(AND(IFERROR($T6<>"",FALSE()),IFERROR($Y6<>"",FALSE()),IF(IFERROR($Z6<>"",FALSE()),IFERROR(AND(ISNUMBER($Z6),$Z6>=DATE(2020,1,1),$Z6<=DATE(2100,12,31)),FALSE()),NOT(ISERROR($Z6))))),FALSE()),"Criticality below baseline: review missing / invalid (T,Y,Z)","")) | AW6: =_xlfn.TEXTJOIN("; ",TRUE(),IF($AJ6>0,"Invalid response value (K)",""),IF($AK6>0,"Likelihood/Impact missing or not integer 1-5 (G,H)",""),IF($AL6>0,"Invalid status value (S)",""),IF($AM6>0,_xlfn.TEXTJOIN("; ",TRUE(),IF(IFERROR(AND($S6="Accepted Risk",$X6=""),FALSE()),"Exemption reference (X) missing",""),IF(IFERROR(AND($S6="Accepted Risk",$Y6=""),FALSE()),"Exemption approver (Y) missing",""),IF(IFERROR(AND($S6="Accepted Risk",$Z6=""),FALSE()),"Exemption date (Z) missing",""),IF(ISERROR($Z6),"Exemption date (Z) invalid - error value",IF(IFERROR(AND($Z6<>"",NOT(AND(ISNUMBER($Z6),$Z6>=DATE(2020,1,1),$Z6<=DATE(2100,12,31)))),FALSE()),"Exemption date (Z) invalid - enter a real date","")),IF(OR(ISERROR($S6),ISERROR($X6),ISERROR($Y6)),"Exemption inputs contain an error value (S,X,Y)","")),""),IF($AG6>0,"Input/calculation fault at "&$AU6,""),IF($AN6>0,"N/A on applicable row",""))
