Workbook
Name Conf_Adjust: Scales!$B$39:$C$41
Name Conf_Check: Scales!$B$39:$D$41
Name GateTab: 'Readiness gate'!$A$7:$K$36
Name List_Appetite: Policy!$C$4:$E$4
Name List_Blast: Scales!$B$31:$B$33
Name List_Confidence: Scales!$B$39:$B$41
Name List_Levels: Scales!$B$6:$B$10
Name List_Reversibility: Scales!$B$24:$B$27
Name List_Steps: Scales!$B$15:$B$20
Name List_YesNo: Scales!$B$54:$B$55

Sheet Guide
A1: Guide
A2: Working tool for the briefing "Auf dem Weg zum autonomen SOC" (M. Muhlert). Version 1.4.3, merged from three prototypes (SOC-Autonomy-Map as the base, SOC-Autonomie-Steuerungstool, Autonomy Decision Planner) and hardened through four independent validation reviews; the change log at the end of this sheet lists what the last two changed. Design law: less evidence must never produce more autonomy.
B4: The logic
B5: 1 | C5: Every use case is split into six process steps: Enrich, Triage, Contain, Eradicate, Recover, Notify. Autonomy belongs to an action in a step, not to a whole use case.
B6: 2 | C6: Each action is rated on reversibility (the guiding principle) and on blast radius. An action is only as reversible as its least reversible element.
B7: 3 | C7: The policy matrix turns that rating into the recommended level for each risk appetite. The recommendation is pure policy - the target picture. The appetite applies by default; a use case can carry its own appetite (its delegation profile).
B8: 4 | C8: You follow the recommendation or choose differently per step. A more cautious choice applies at once. A choice above policy stays visible as a target and releases with a recorded approval: Exception approved = Yes.
B9: 5 | C9: Three constraints decide the release candidate, what may run today: model confidence (High sets no ceiling; Medium and Low cap one or two levels below the policy level; floor L1; read-only steps are exempt), the readiness gate (not passed: hold at current; passed: state-changing steps climb one level, read-only steps release fully), and the non-waivable human-signature guardrail (state-changing irreversible or high-blast actions never release above L3, referenced to the Scales labels).
B10: 6 | C10: 'Limited by' names the binding constraint: readiness gate, model confidence, exception not approved, human-signature guardrail, own choice - or none. When several bind at the same level, all are named, joined by +. A row with missing inputs says Incomplete assessment and computes no candidate.
B11: 7 | C11: The scenario view puts target and today side by side: Standard assets (target) and Critical assets (target) are target pictures (critical re-rates every row at High blast radius), Released today shows release candidates. A target can sit above Released today; that gap is the point of the comparison.
B13: How to use it
B14: Autonomy map | C14: Choose the default risk appetite and the scenario view in the two yellow cells. The heatmap, counters and chart recalculate. All counters follow the selected view.
B15: Use cases | C15: Set a different appetite for single use cases (yellow column). IDs must stay unique; the Integrity column warns about duplicates, and a duplicate key blanks the affected register rows.
B16: Register | C16: Check action, reversibility, blast radius and model confidence for each step (blue). Your decisions sit in the yellow columns: your choice, exception approval, current level. Action, both ratings, confidence and current level are required: until all five are filled the row reads Incomplete assessment and no target and no release candidate is computed (the policy level in column J shows as soon as reversibility and blast radius are set). Columns I, K and L are grouped; the outline buttons above the columns collapse them.
B17: Readiness gate | C17: Answer the six criteria per use case with Yes or No. IDs are stable keys with uniqueness enforced: a duplicated key produces Incomplete, never an uplift. Only six explicit Yes answers pass. The yellow setting in row 4 decides what read-only steps need (default: all six criteria).
B18: Policy | C18: Change the matrix if none of the three profiles fits your organisation (whole levels 0 to 4). The guardrail column warns above L3 for irreversible or high-blast state changes; the release guardrail in the Register is non-waivable. A configuration-integrity cell checks the matrix.
B19: Scales | C19: Definitions of levels, steps, reversibility, blast radius, model confidence, gate criteria and verdicts. The confidence adjustments are editable governance conventions; a config check marks missing or invalid values, which then cap at L1.
B21: How to read it
B22: Autonomy levels | C22: The briefing assigns L0 to L5 per use case. Here the same scale is read per process step, as the split of work between human and system in that step.
B23: Recommended level | C23: Pure policy: risk appetite, reversibility, blast radius. This is the target picture. Confidence does not lower it - an ambitious target stays visible as a target.
B24: Model confidence | C24: Rated per task type. High means proven and calibrated and sets no ceiling; Medium and Low cap the release candidate below the policy level. A missing or unknown rating, or a broken adjustment on Scales, caps at L1: less evidence never produces more autonomy.
B25: Release candidate | C25: What may run today in the standard context, after confidence ceiling, gate allowance and the human-signature guardrail. Read-only steps are exempt from confidence and from one-level staging: once the gate passes, they release fully (briefing, slide 7). It remains a candidate: formal authorization stays with the Control Tower (slide 17), and the tool assumes actions, accesses and data uses are already permitted.
B26: Critical assets | C26: A target sensitivity view: production and business-critical services, board and VIP accounts, OT, supplier connections. Every row counts as High blast radius and shows the lower level.
B27: First human gate | C27: The first step in the chain that needs a human in this view. It assumes a linear path; a runtime response may branch or notify earlier.
B28: L5 | C28: Self-improving is not part of the map. It stays in test and detection engineering.
B30: Cell colours
B31: Yellow fill | C31: Your decisions: risk appetite, scenario view, appetite per use case, your own level, exception approval, current level.
B32: Blue text | C32: Pre-filled content that you can edit: actions, ratings, confidence, policy values, definitions, gate answers.
B33: Black text | C33: Calculated. Do not overwrite. Colour reinforces the text; it never carries the meaning alone.
B35: Extending
B36: New use case | C36: Rows are prepared for UC21 to UC30: add name and domain on Use cases, fill the six prepared Register rows (action, ratings, confidence, current level) and answer the gate. The map fills itself.
B37: Capacity | C37: Supported capacity is 30 use cases. Beyond UC30, add rows on all four sheets and extend every named range and row bound - copying rows alone is not enough.
B38: Renaming | C38: Change a class or step name on Scales and reselect it where used. Calculations reference the Scales cells, so renaming is safe everywhere, including the guardrail. The map marks duplicate use-case-step pairs as Dup. instead of summing levels.
B40: Pre-filled content and sources
B41: Ratings | C41: All actions and ratings are a starting proposal built from the twenty playbooks of the briefing (slides 11 and 15). They assume standard assets and are not a standard.
B42: Three corrections | C42: UC01 and UC02 Contain read blast radius Medium: quarantine across all mailboxes is not 'one mailbox' by the tool's own definition. UC02 carries Progressive, same as UC01: the briefing gives the whole mail class a high delegation profile and says quarantine and mass remediation can run fully automatically (slides 9, 15, 16).
B43: Confidence | C43: Model confidence is an illustrative starting point and a chosen governance rule, not a measurement. Replace it with evidence: precision and false-positive rates per detection, and calibration checks after every model or prompt change (briefing, slide 14).
B44: Policy values | C44: The matrix follows the briefing: L3 to L4 for common incidents, L2 to L3 for highly critical ones; irreversible and business-critical actions need a human signature (slides 3, 4 and 15).
B45: Appetite examples | C45: UC01 and UC02 are set to Progressive and UC20 to Conservative, following the briefing's delegation intents (slide 16).
B46: Readiness criteria | C46: The six gate criteria come from the readiness gate of the briefing (slide 16). Criterion 2 asks for a documented and tested rollback path; reversibility itself is already rated per step.
...

Sheet Autonomy map
A1: SOC Autonomy Map
A2: Autonomy level per use case and process step. The target is pure policy: risk appetite, reversibility, blast radius. Model confidence, the readiness gate and the human-signature guardrail decide the release candidate. Version 1.4.3.
A4: Risk appetite (default) | C4: Progressive | E4: Runs autonomously (L4) | G4: Human approves (L3) | I4: Human decides (L0 to L2) | K4: Choices above policy | M4: Readiness gates passed | O4: Steps not fully released | Q4: Incomplete rows | S4: Current above permitted
A5: Scenario view | C5: Released today | E5: =IF(COUNT($E$8:$J$37)=0,0,COUNTIF($E$8:$J$37,4)/COUNT($E$8:$J$37)) -> 0.11666667 | G5: =IF(COUNT($E$8:$J$37)=0,0,COUNTIF($E$8:$J$37,3)/COUNT($E$8:$J$37)) -> 0.091666667 | I5: =IF(COUNT($E$8:$J$37)=0,0,COUNTIF($E$8:$J$37,"<3")/COUNT($E$8:$J$37)) -> 0.79166667 | K5: =COUNTIF(Register!$P$6:$P$185,"Above policy*") -> 0 | M5: =COUNTIF('Readiness gate'!$I$7:$I$36,"Passed")&" of "&COUNTA('Use cases'!$B$5:$B$34) -> 11 of 20 | O5: =SUMPRODUCT((Register!$O$6:$O$185<>"")*(Register!$T$6:$T$185<>"")*(Register!$T$6:$T$185<Register!$O$6:$O$185)) -> 105 | Q5: =SUMPRODUCT((Register!$B$6:$B$185<>"")*(Register!$O$6:$O$185="")) -> 0 | S5: =SUMPRODUCT((Register!$R$6:$R$185<>"")*(Register!$T$6:$T$185<>"")*(Register!$R$6:$R$185>Register!$T$6:$T$185)) -> 0
A6: =IF(OR(Policy!$B$24<>"OK",Scales!$C$43<>"OK"),"Configuration error: "&IF(Policy!$B$24<>"OK",Policy!$B$24&" (Policy sheet; no level is computed until it reads OK)","")&IF(AND(Policy!$B$24<>"OK",Scales!$C$43<>"OK"),"; ","")&IF(Scales!$C$43<>"OK",Scales!$C$43&" (Scales sheet; affected ratings cap at L1 until it reads OK)","")&".","This view: "&$C$5&" - "&IF($C$5="Released today","release candidates in the standard context (what may run today)","target picture (what the policy allows)")&". Formal authorization stays with the Control Tower.") -> This view: Released today - release candidates in the standard context (what may run today). Formal authorization stays with the Control Tower.
A7: ID | B7: Use case | C7: Domain | D7: Appetite | E7: =Scales!$B$15 -> Enrich | F7: =Scales!$B$16 -> Triage | G7: =Scales!$B$17 -> Contain | H7: =Scales!$B$18 -> Eradicate | I7: =Scales!$B$19 -> Recover | J7: =Scales!$B$20 -> Notify | K7: ="First human gate ("&IF($C$5="Released today","released","target")&")" -> First human gate (released) | L7: Above policy | M7: Readiness gate | N7: Steps not fully released
A8: =IF('Use cases'!$B$5="","",'Use cases'!$A$5) -> UC01 | B8: =IF($A8="","",'Use cases'!$B$5) -> Phishing campaign containment | C8: =IF($A8="","",'Use cases'!$C$5) -> Email and collaboration | D8: =IF($A8="","",'Use cases'!$E$5) -> Progressive | E8: =IF($A8="","",IF(COUNTIFS(Register!$A$6:$A$185,$A8,Register!$D$6:$D$185,E$7)>1,"Dup.",IF($C$5="Critical assets (target)",IF(COUNTIFS(Register!$A$6:$A$185,$A8,Register!$D$6:$D$185,E$7,Register!$Q$6:$Q$185,">=0")=0,"",SUMIFS(Register!$Q$6:$Q$185,Register!$A$6:$A$185,$A8,Register!$D$6:$D$185,E$7)),IF($C$5="Released today",IF(COUNTIFS(Register!$A$6:$A$185,$A8,Register!$D$6:$D$185,E$7,Register!$T$6:$T$185,">=0")=0,"",SUMIFS(Register!$T$6:$T$185,Register!$A$6:$A$185,$A8,Register!$D$6:$D$185,E$7)),IF(COUNTIFS(Register!$A$6:$A$185,$A8,Register!$D$6:$D$185,E$7,Register!$O$6:$O$185,">=0")=0,"",SUMIFS(Register!$O$6:$O$185,Register!$A$6:$A$185,$A8,Register!$D$6:$D$185,E$7)))))) -> 4 | F8: =IF($A8="","",IF(COUNTIFS(Register!$A$6:$A$185,$A8,Register!$D$6:$D$185,F$7)>1,"Dup.",IF($C$5="Critical assets (target)",IF(COUNTIFS(Register!$A$6:$A$185,$A8,Register!$D$6:$D$185,F$7,Register!$Q$6:$Q$185,">=0")=0,"",SUMIFS(Register!$Q$6:$Q$185,Register!$A$6:$A$185,$A8,Register!$D$6:$D$185,F$7)),IF($C$5="Released today",IF(COUNTIFS(Register!$A$6:$A$185,$A8,Register!$D$6:$D$185,F$7,Register!$T$6:$T$185,">=0")=0,"",SUMIFS(Register!$T$6:$T$185,Register!$A$6:$A$185,$A8,Register!$D$6:$D$185,F$7)),IF(COUNTIFS(Register!$A$6:$A$185,$A8,Register!$D$6:$D$185,F$7,Register!$O$6:$O$185,">=0")=0,"",SUMIFS(Register!$O$6:$O$185,Register!$A$6:$A$185,$A8,Register!$D$6:$D$185,F$7)))))) -> 3 | G8: =IF($A8="","",IF(COUNTIFS(Register!$A$6:$A$185,$A8,Register!$D$6:$D$185,G$7)>1,"Dup.",IF($C$5="Critical assets (target)",IF(COUNTIFS(Register!$A$6:$A$185,$A8,Register!$D$6:$D$185,G$7,Register!$Q$6:$Q$185,">=0")=0,"",SUMIFS(Register!$Q$6:$Q$185,Register!$A$6:$A$185,$A8,Register!$D$6:$D$185,G$7)),IF($C$5="Released today",IF(COUNTIFS(Register!$A$6:$A$185,$A8,Register!$D$6:$D$185,G$7,Register!$T$6:$T$185,">=0")=0,"",SUMIFS(Register!$T$6:$T$185,Register!$A$6:$A$185,$A8,Register!$D$6:$D$185,G$7)),IF(COUNTIFS(Register!$A$6:$A$185,$A8,Register!$D$6:$D$185,G$7,Register!$O$6:$O$185,">=0")=0,"",SUMIFS(Register!$O$6:$O$185,Register!$A$6:$A$185,$A8,Register!$D$6:$D$185,G$7)))))) -> 4 | H8: =IF($A8="","",IF(COUNTIFS(Register!$A$6:$A$185,$A8,Register!$D$6:$D$185,H$7)>1,"Dup.",IF($C$5="Critical assets (target)",IF(COUNTIFS(Register!$A$6:$A$185,$A8,Register!$D$6:$D$185,H$7,Register!$Q$6:$Q$185,">=0")=0,"",SUMIFS(Register!$Q$6:$Q$185,Register!$A$6:$A$185,$A8,Register!$D$6:$D$185,H$7)),IF($C$5="Released today",IF(COUNTIFS(Register!$A$6:$A$185,$A8,Register!$D$6:$D$185,H$7,Register!$T$6:$T$185,">=0")=0,"",SUMIFS(Register!$T$6:$T$185,Register!$A$6:$A$185,$A8,Register!$D$6:$D$185,H$7)),IF(COUNTIFS(Register!$A$6:$A$185,$A8,Register!$D$6:$D$185,H$7,Register!$O$6:$O$185,">=0")=0,"",SUMIFS(Register!$O$6:$O$185,Register!$A$6:$A$185,$A8,Register!$D$6:$D$185,H$7)))))) -> 3 | I8: =IF($A8="","",IF(COUNTIFS(Register!$A$6:$A$185,$A8,Register!$D$6:$D$185,I$7)>1,"Dup.",IF($C$5="Critical assets (target)",IF(COUNTIFS(Register!$A$6:$A$185,$A8,Register!$D$6:$D$185,I$7,Register!$Q$6:$Q$185,">=0")=0,"",SUMIFS(Register!$Q$6:$Q$185,Register!$A$6:$A$185,$A8,Register!$D$6:$D$185,I$7)),IF($C$5="Released today",IF(COUNTIFS(Register!$A$6:$A$185,$A8,Register!$D$6:$D$185,I$7,Register!$T$6:$T$185,">=0")=0,"",SUMIFS(Register!$T$6:$T$185,Register!$A$6:$A$185,$A8,Register!$D$6:$D$185,I$7)),IF(COUNTIFS(Register!$A$6:$A$185,$A8,Register!$D$6:$D$185,I$7,Register!$O$6:$O$185,">=0")=0,"",SUMIFS(Register!$O$6:$O$185,Register!$A$6:$A$185,$A8,Register!$D$6:$D$185,I$7)))))) -> 2 | J8: =IF($A8="","",IF(COUNTIFS(Register!$A$6:$A$185,$A8,Register!$D$6:$D$185,J$7)>1,"Dup.",IF($C$5="Critical assets (target)",IF(COUNTIFS(Register!$A$6:$A$185,$A8,Register!$D$6:$D$185,J$7,Register!$Q$6:$Q$185,">=0")=0,"",SUMIFS(Register!$Q$6:$Q$185,Register!$A$6:$A$185,$A8,Register!$D$6:$D$185,J$7)),IF($C$5="Released today",IF(COUNTIFS(Register!$A$6:$A$185,$A8,Register!$D$6:$D$185,J$7,Register!$T$6:$T$185,">=0")=0,"",SUMIFS(Register!$T$6:$T$185,Register!$A$6:$A$185,$A8,Register!$D$6:$D$185,J$7)),IF(COUNTIFS(Register!$A$6:$A$185,$A8,Register!$D$6:$D$185,J$7,Register!$O$6:$O$185,">=0")=0,"",SUMIFS(Register!$O$6:$O$185,Register!$A$6:$A$185,$A8,Register!$D$6:$D$185,J$7)))))) -> 3 | K8: =IF($A8="","",IF(COUNT(E8:J8)<6,"Incomplete",IF(AND(ISNUMBER(E8),E8<4),E$7,IF(AND(ISNUMBER(F8),F8<4),F$7,IF(AND(ISNUMBER(G8),G8<4),G$7,IF(AND(ISNUMBER(H8),H8<4),H$7,IF(AND(ISNUMBER(I8),I8<4),I$7,IF(AND(ISNUMBER(J8),J8<4),J$7,"None")))))))) -> Triage | L8: =IF($A8="","",COUNTIFS(Register!$A$6:$A$185,$A8,Register!$P$6:$P$185,"Above policy*")) -> 0 | M8: =IF($A8="","",IF(COUNTIF('Readiness gate'!$A$7:$A$36,$A8)<>1,"Incomplete",IFERROR(IF(VLOOKUP($A8,GateTab,9,FALSE())="","Incomplete",VLOOKUP($A8,GateTab,9,FALSE())),"Incomplete"))) -> Passed | N8: =IF($A8="","",SUMPRODUCT((Register!$A$6:$A$185=$A8)*(Register!$T$6:$T$185<>"")*(Register!$O$6:$O$185<>"")*(Register!$T$6:$T$185<Register!$O$6:$O$185))) -> 4
A9: =IF('Use cases'!$B$6="","",'Use cases'!$A$6) -> UC02 | B9: =IF($A9="","",'Use cases'!$B$6) -> Malicious attachment detonation and mailbox clean-up | C9: =IF($A9="","",'Use cases'!$C$6) -> Email and collaboration | D9: =IF($A9="","",'Use cases'!$E$6) -> Progressive | E9: =IF($A9="","",IF(COUNTIFS(Register!$A$6:$A$185,$A9,Register!$D$6:$D$185,E$7)>1,"Dup.",IF($C$5="Critical assets (target)",IF(COUNTIFS(Register!$A$6:$A$185,$A9,Register!$D$6:$D$185,E$7,Register!$Q$6:$Q$185,">=0")=0,"",SUMIFS(Register!$Q$6:$Q$185,Register!$A$6:$A$185,$A9,Register!$D$6:$D$185,E$7)),IF($C$5="Released today",IF(COUNTIFS(Register!$A$6:$A$185,$A9,Register!$D$6:$D$185,E$7,Register!$T$6:$T$185,">=0")=0,"",SUMIFS(Register!$T$6:$T$185,Register!$A$6:$A$185,$A9,Register!$D$6:$D$185,E$7)),IF(COUNTIFS(Register!$A$6:$A$185,$A9,Register!$D$6:$D$185,E$7,Register!$O$6:$O$185,">=0")=0,"",SUMIFS(Register!$O$6:$O$185,Register!$A$6:$A$185,$A9,Register!$D$6:$D$185,E$7)))))) -> 4 | F9: =IF($A9="","",IF(COUNTIFS(Register!$A$6:$A$185,$A9,Register!$D$6:$D$185,F$7)>1,"Dup.",IF($C$5="Critical assets (target)",IF(COUNTIFS(Register!$A$6:$A$185,$A9,Register!$D$6:$D$185,F$7,Register!$Q$6:$Q$185,">=0")=0,"",SUMIFS(Register!$Q$6:$Q$185,Register!$A$6:$A$185,$A9,Register!$D$6:$D$185,F$7)),IF($C$5="Released today",IF(COUNTIFS(Register!$A$6:$A$185,$A9,Register!$D$6:$D$185,F$7,Register!$T$6:$T$185,">=0")=0,"",SUMIFS(Register!$T$6:$T$185,Register!$A$6:$A$185,$A9,Register!$D$6:$D$185,F$7)),IF(COUNTIFS(Register!$A$6:$A$185,$A9,Register!$D$6:$D$185,F$7,Register!$O$6:$O$185,">=0")=0,"",SUMIFS(Register!$O$6:$O$185,Register!$A$6:$A$185,$A9,Register!$D$6:$D$185,F$7)))))) -> 2 | G9: =IF($A9="","",IF(COUNTIFS(Register!$A$6:$A$185,$A9,Register!$D$6:$D$185,G$7)>1,"Dup.",IF($C$5="Critical assets (target)",IF(COUNTIFS(Register!$A$6:$A$185,$A9,Register!$D$6:$D$185,G$7,Register!$Q$6:$Q$185,">=0")=0,"",SUMIFS(Register!$Q$6:$Q$185,Register!$A$6:$A$185,$A9,Register!$D$6:$D$185,G$7)),IF($C$5="Released today",IF(COUNTIFS(Register!$A$6:$A$185,$A9,Register!$D$6:$D$185,G$7,Register!$T$6:$T$185,">=0")=0,"",SUMIFS(Register!$T$6:$T$185,Register!$A$6:$A$185,$A9,Register!$D$6:$D$185,G$7)),IF(COUNTIFS(Register!$A$6:$A$185,$A9,Register!$D$6:$D$185,G$7,Register!$O$6:$O$185,">=0")=0,"",SUMIFS(Register!$O$6:$O$185,Register!$A$6:$A$185,$A9,Register!$D$6:$D$185,G$7)))))) -> 3 | H9: =IF($A9="","",IF(COUNTIFS(Register!$A$6:$A$185,$A9,Register!$D$6:$D$185,H$7)>1,"Dup.",IF($C$5="Critical assets (target)",IF(COUNTIFS(Register!$A$6:$A$185,$A9,Register!$D$6:$D$185,H$7,Register!$Q$6:$Q$185,">=0")=0,"",SUMIFS(Register!$Q$6:$Q$185,Register!$A$6:$A$185,$A9,Register!$D$6:$D$185,H$7)),IF($C$5="Released today",IF(COUNTIFS(Register!$A$6:$A$185,$A9,Register!$D$6:$D$185,H$7,Register!$T$6:$T$185,">=0")=0,"",SUMIFS(Register!$T$6:$T$185,Register!$A$6:$A$185,$A9,Register!$D$6:$D$185,H$7)),IF(COUNTIFS(Register!$A$6:$A$185,$A9,Register!$D$6:$D$185,H$7,Register!$O$6:$O$185,">=0")=0,"",SUMIFS(Register!$O$6:$O$185,Register!$A$6:$A$185,$A9,Register!$D$6:$D$185,H$7)))))) -> 2 | I9: =IF($A9="","",IF(COUNTIFS(Register!$A$6:$A$185,$A9,Register!$D$6:$D$185,I$7)>1,"Dup.",IF($C$5="Critical assets (target)",IF(COUNTIFS(Register!$A$6:$A$185,$A9,Register!$D$6:$D$185,I$7,Register!$Q$6:$Q$185,">=0")=0,"",SUMIFS(Register!$Q$6:$Q$185,Register!$A$6:$A$185,$A9,Register!$D$6:$D$185,I$7)),IF($C$5="Released today",IF(COUNTIFS(Register!$A$6:$A$185,$A9,Register!$D$6:$D$185,I$7,Register!$T$6:$T$185,">=0")=0,"",SUMIFS(Register!$T$6:$T$185,Register!$A$6:$A$185,$A9,Register!$D$6:$D$185,I$7)),IF(COUNTIFS(Register!$A$6:$A$185,$A9,Register!$D$6:$D$185,I$7,Register!$O$6:$O$185,">=0")=0,"",SUMIFS(Register!$O$6:$O$185,Register!$A$6:$A$185,$A9,Register!$D$6:$D$185,I$7)))))) -> 2 | J9: =IF($A9="","",IF(COUNTIFS(Register!$A$6:$A$185,$A9,Register!$D$6:$D$185,J$7)>1,"Dup.",IF($C$5="Critical assets (target)",IF(COUNTIFS(Register!$A$6:$A$185,$A9,Register!$D$6:$D$185,J$7,Register!$Q$6:$Q$185,">=0")=0,"",SUMIFS(Register!$Q$6:$Q$185,Register!$A$6:$A$185,$A9,Register!$D$6:$D$185,J$7)),IF($C$5="Released today",IF(COUNTIFS(Register!$A$6:$A$185,$A9,Register!$D$6:$D$185,J$7,Register!$T$6:$T$185,">=0")=0,"",SUMIFS(Register!$T$6:$T$185,Register!$A$6:$A$185,$A9,Register!$D$6:$D$185,J$7)),IF(COUNTIFS(Register!$A$6:$A$185,$A9,Register!$D$6:$D$185,J$7,Register!$O$6:$O$185,">=0")=0,"",SUMIFS(Register!$O$6:$O$185,Register!$A$6:$A$185,$A9,Register!$D$6:$D$185,J$7)))))) -> 2 | K9: =IF($A9="","",IF(COUNT(E9:J9)<6,"Incomplete",IF(AND(ISNUMBER(E9),E9<4),E$7,IF(AND(ISNUMBER(F9),F9<4),F$7,IF(AND(ISNUMBER(G9),G9<4),G$7,IF(AND(ISNUMBER(H9),H9<4),H$7,IF(AND(ISNUMBER(I9),I9<4),I$7,IF(AND(ISNUMBER(J9),J9<4),J$7,"None")))))))) -> Triage | L9: =IF($A9="","",COUNTIFS(Register!$A$6:$A$185,$A9,Register!$P$6:$P$185,"Above policy*")) -> 0 | M9: =IF($A9="","",IF(COUNTIF('Readiness gate'!$A$7:$A$36,$A9)<>1,"Incomplete",IFERROR(IF(VLOOKUP($A9,GateTab,9,FALSE())="","Incomplete",VLOOKUP($A9,GateTab,9,FALSE())),"Incomplete"))) -> Passed | N9: =IF($A9="","",SUMPRODUCT((Register!$A$6:$A$185=$A9)*(Register!$T$6:$T$185<>"")*(Register!$O$6:$O$185<>"")*(Register!$T$6:$T$185<Register!$O$6:$O$185))) -> 5
A10: =IF('Use cases'!$B$7="","",'Use cases'!$A$7) -> UC03 | B10: =IF($A10="","",'Use cases'!$B$7) -> OAuth consent abuse | C10: =IF($A10="","",'Use cases'!$C$7) -> Identity | D10: =IF($A10="","",'Use cases'!$E$7) -> Progressive | E10: =IF($A10="","",IF(COUNTIFS(Register!$A$6:$A$185,$A10,Register!$D$6:$D$185,E$7)>1,"Dup.",IF($C$5="Critical assets (target)",IF(COUNTIFS(Register!$A$6:$A$185,$A10,Register!$D$6:$D$185,E$7,Register!$Q$6:$Q$185,">=0")=0,"",SUMIFS(Register!$Q$6:$Q$185,Register!$A$6:$A$185,$A10,Register!$D$6:$D$185,E$7)),IF($C$5="Released today",IF(COUNTIFS(Register!$A$6:$A$185,$A10,Register!$D$6:$D$185,E$7,Register!$T$6:$T$185,">=0")=0,"",SUMIFS(Register!$T$6:$T$185,Register!$A$6:$A$185,$A10,Register!$D$6:$D$185,E$7)),IF(COUNTIFS(Register!$A$6:$A$185,$A10,Register!$D$6:$D$185,E$7,Register!$O$6:$O$185,">=0")=0,"",SUMIFS(Register!$O$6:$O$185,Register!$A$6:$A$185,$A10,Register!$D$6:$D$185,E$7)))))) -> 4 | F10: =IF($A10="","",IF(COUNTIFS(Register!$A$6:$A$185,$A10,Register!$D$6:$D$185,F$7)>1,"Dup.",IF($C$5="Critical assets (target)",IF(COUNTIFS(Register!$A$6:$A$185,$A10,Register!$D$6:$D$185,F$7,Register!$Q$6:$Q$185,">=0")=0,"",SUMIFS(Register!$Q$6:$Q$185,Register!$A$6:$A$185,$A10,Register!$D$6:$D$185,F$7)),IF($C$5="Released today",IF(COUNTIFS(Register!$A$6:$A$185,$A10,Register!$D$6:$D$185,F$7,Register!$T$6:$T$185,">=0")=0,"",SUMIFS(Register!$T$6:$T$185,Register!$A$6:$A$185,$A10,Register!$D$6:$D$185,F$7)),IF(COUNTIFS(Register!$A$6:$A$185,$A10,Register!$D$6:$D$185,F$7,Register!$O$6:$O$185,">=0")=0,"",SUMIFS(Register!$O$6:$O$185,Register!$A$6:$A$185,$A10,Register!$D$6:$D$185,F$7)))))) -> 2 | G10: =IF($A10="","",IF(COUNTIFS(Register!$A$6:$A$185,$A10,Register!$D$6:$D$185,G$7)>1,"Dup.",IF($C$5="Critical assets (target)",IF(COUNTIFS(Register!$A$6:$A$185,$A10,Register!$D$6:$D$185,G$7,Register!$Q$6:$Q$185,">=0")=0,"",SUMIFS(Register!$Q$6:$Q$185,Register!$A$6:$A$185,$A10,Register!$D$6:$D$185,G$7)),IF($C$5="Released today",IF(COUNTIFS(Register!$A$6:$A$185,$A10,Register!$D$6:$D$185,G$7,Register!$T$6:$T$185,">=0")=0,"",SUMIFS(Register!$T$6:$T$185,Register!$A$6:$A$185,$A10,Register!$D$6:$D$185,G$7)),IF(COUNTIFS(Register!$A$6:$A$185,$A10,Register!$D$6:$D$185,G$7,Register!$O$6:$O$185,">=0")=0,"",SUMIFS(Register!$O$6:$O$185,Register!$A$6:$A$185,$A10,Register!$D$6:$D$185,G$7)))))) -> 3 | H10: =IF($A10="","",IF(COUNTIFS(Register!$A$6:$A$185,$A10,Register!$D$6:$D$185,H$7)>1,"Dup.",IF($C$5="Critical assets (target)",IF(COUNTIFS(Register!$A$6:$A$185,$A10,Register!$D$6:$D$185,H$7,Register!$Q$6:$Q$185,">=0")=0,"",SUMIFS(Register!$Q$6:$Q$185,Register!$A$6:$A$185,$A10,Register!$D$6:$D$185,H$7)),IF($C$5="Released today",IF(COUNTIFS(Register!$A$6:$A$185,$A10,Register!$D$6:$D$185,H$7,Register!$T$6:$T$185,">=0")=0,"",SUMIFS(Register!$T$6:$T$185,Register!$A$6:$A$185,$A10,Register!$D$6:$D$185,H$7)),IF(COUNTIFS(Register!$A$6:$A$185,$A10,Register!$D$6:$D$185,H$7,Register!$O$6:$O$185,">=0")=0,"",SUMIFS(Register!$O$6:$O$185,Register!$A$6:$A$185,$A10,Register!$D$6:$D$185,H$7)))))) -> 2 | I10: =IF($A10="","",IF(COUNTIFS(Register!$A$6:$A$185,$A10,Register!$D$6:$D$185,I$7)>1,"Dup.",IF($C$5="Critical assets (target)",IF(COUNTIFS(Register!$A$6:$A$185,$A10,Register!$D$6:$D$185,I$7,Register!$Q$6:$Q$185,">=0")=0,"",SUMIFS(Register!$Q$6:$Q$185,Register!$A$6:$A$185,$A10,Register!$D$6:$D$185,I$7)),IF($C$5="Released today",IF(COUNTIFS(Register!$A$6:$A$185,$A10,Register!$D$6:$D$185,I$7,Register!$T$6:$T$185,">=0")=0,"",SUMIFS(Register!$T$6:$T$185,Register!$A$6:$A$185,$A10,Register!$D$6:$D$185,I$7)),IF(COUNTIFS(Register!$A$6:$A$185,$A10,Register!$D$6:$D$185,I$7,Register!$O$6:$O$185,">=0")=0,"",SUMIFS(Register!$O$6:$O$185,Register!$A$6:$A$185,$A10,Register!$D$6:$D$185,I$7)))))) -> 2 | J10: =IF($A10="","",IF(COUNTIFS(Register!$A$6:$A$185,$A10,Register!$D$6:$D$185,J$7)>1,"Dup.",IF($C$5="Critical assets (target)",IF(COUNTIFS(Register!$A$6:$A$185,$A10,Register!$D$6:$D$185,J$7,Register!$Q$6:$Q$185,">=0")=0,"",SUMIFS(Register!$Q$6:$Q$185,Register!$A$6:$A$185,$A10,Register!$D$6:$D$185,J$7)),IF($C$5="Released today",IF(COUNTIFS(Register!$A$6:$A$185,$A10,Register!$D$6:$D$185,J$7,Register!$T$6:$T$185,">=0")=0,"",SUMIFS(Register!$T$6:$T$185,Register!$A$6:$A$185,$A10,Register!$D$6:$D$185,J$7)),IF(COUNTIFS(Register!$A$6:$A$185,$A10,Register!$D$6:$D$185,J$7,Register!$O$6:$O$185,">=0")=0,"",SUMIFS(Register!$O$6:$O$185,Register!$A$6:$A$185,$A10,Register!$D$6:$D$185,J$7)))))) -> 2 | K10: =IF($A10="","",IF(COUNT(E10:J10)<6,"Incomplete",IF(AND(ISNUMBER(E10),E10<4),E$7,IF(AND(ISNUMBER(F10),F10<4),F$7,IF(AND(ISNUMBER(G10),G10<4),G$7,IF(AND(ISNUMBER(H10),H10<4),H$7,IF(AND(ISNUMBER(I10),I10<4),I$7,IF(AND(ISNUMBER(J10),J10<4),J$7,"None")))))))) -> Triage | L10: =IF($A10="","",COUNTIFS(Register!$A$6:$A$185,$A10,Register!$P$6:$P$185,"Above policy*")) -> 0 | M10: =IF($A10="","",IF(COUNTIF('Readiness gate'!$A$7:$A$36,$A10)<>1,"Incomplete",IFERROR(IF(VLOOKUP($A10,GateTab,9,FALSE())="","Incomplete",VLOOKUP($A10,GateTab,9,FALSE())),"Incomplete"))) -> Passed | N10: =IF($A10="","",SUMPRODUCT((Register!$A$6:$A$185=$A10)*(Register!$T$6:$T$185<>"")*(Register!$O$6:$O$185<>"")*(Register!$T$6:$T$185<Register!$O$6:$O$185))) -> 5
A11: =IF('Use cases'!$B$8="","",'Use cases'!$A$8) -> UC04 | B11: =IF($A11="","",'Use cases'!$B$8) -> Suspicious MFA registration | C11: =IF($A11="","",'Use cases'!$C$8) -> Identity | D11: =IF($A11="","",'Use cases'!$E$8) -> Progressive | E11: =IF($A11="","",IF(COUNTIFS(Register!$A$6:$A$185,$A11,Register!$D$6:$D$185,E$7)>1,"Dup.",IF($C$5="Critical assets (target)",IF(COUNTIFS(Register!$A$6:$A$185,$A11,Register!$D$6:$D$185,E$7,Register!$Q$6:$Q$185,">=0")=0,"",SUMIFS(Register!$Q$6:$Q$185,Register!$A$6:$A$185,$A11,Register!$D$6:$D$185,E$7)),IF($C$5="Released today",IF(COUNTIFS(Register!$A$6:$A$185,$A11,Register!$D$6:$D$185,E$7,Register!$T$6:$T$185,">=0")=0,"",SUMIFS(Register!$T$6:$T$185,Register!$A$6:$A$185,$A11,Register!$D$6:$D$185,E$7)),IF(COUNTIFS(Register!$A$6:$A$185,$A11,Register!$D$6:$D$185,E$7,Register!$O$6:$O$185,">=0")=0,"",SUMIFS(Register!$O$6:$O$185,Register!$A$6:$A$185,$A11,Register!$D$6:$D$185,E$7)))))) -> 4 | F11: =IF($A11="","",IF(COUNTIFS(Register!$A$6:$A$185,$A11,Register!$D$6:$D$185,F$7)>1,"Dup.",IF($C$5="Critical assets (target)",IF(COUNTIFS(Register!$A$6:$A$185,$A11,Register!$D$6:$D$185,F$7,Register!$Q$6:$Q$185,">=0")=0,"",SUMIFS(Register!$Q$6:$Q$185,Register!$A$6:$A$185,$A11,Register!$D$6:$D$185,F$7)),IF($C$5="Released today",IF(COUNTIFS(Register!$A$6:$A$185,$A11,Register!$D$6:$D$185,F$7,Register!$T$6:$T$185,">=0")=0,"",SUMIFS(Register!$T$6:$T$185,Register!$A$6:$A$185,$A11,Register!$D$6:$D$185,F$7)),IF(COUNTIFS(Register!$A$6:$A$185,$A11,Register!$D$6:$D$185,F$7,Register!$O$6:$O$185,">=0")=0,"",SUMIFS(Register!$O$6:$O$185,Register!$A$6:$A$185,$A11,Register!$D$6:$D$185,F$7)))))) -> 2 | G11: =IF($A11="","",IF(COUNTIFS(Register!$A$6:$A$185,$A11,Register!$D$6:$D$185,G$7)>1,"Dup.",IF($C$5="Critical assets (target)",IF(COUNTIFS(Register!$A$6:$A$185,$A11,Register!$D$6:$D$185,G$7,Register!$Q$6:$Q$185,">=0")=0,"",SUMIFS(Register!$Q$6:$Q$185,Register!$A$6:$A$185,$A11,Register!$D$6:$D$185,G$7)),IF($C$5="Released today",IF(COUNTIFS(Register!$A$6:$A$185,$A11,Register!$D$6:$D$185,G$7,Register!$T$6:$T$185,">=0")=0,"",SUMIFS(Register!$T$6:$T$185,Register!$A$6:$A$185,$A11,Register!$D$6:$D$185,G$7)),IF(COUNTIFS(Register!$A$6:$A$185,$A11,Register!$D$6:$D$185,G$7,Register!$O$6:$O$185,">=0")=0,"",SUMIFS(Register!$O$6:$O$185,Register!$A$6:$A$185,$A11,Register!$D$6:$D$185,G$7)))))) -> 3 | H11: =IF($A11="","",IF(COUNTIFS(Register!$A$6:$A$185,$A11,Register!$D$6:$D$185,H$7)>1,"Dup.",IF($C$5="Critical assets (target)",IF(COUNTIFS(Register!$A$6:$A$185,$A11,Register!$D$6:$D$185,H$7,Register!$Q$6:$Q$185,">=0")=0,"",SUMIFS(Register!$Q$6:$Q$185,Register!$A$6:$A$185,$A11,Register!$D$6:$D$185,H$7)),IF($C$5="Released today",IF(COUNTIFS(Register!$A$6:$A$185,$A11,Register!$D$6:$D$185,H$7,Register!$T$6:$T$185,">=0")=0,"",SUMIFS(Register!$T$6:$T$185,Register!$A$6:$A$185,$A11,Register!$D$6:$D$185,H$7)),IF(COUNTIFS(Register!$A$6:$A$185,$A11,Register!$D$6:$D$185,H$7,Register!$O$6:$O$185,">=0")=0,"",SUMIFS(Register!$O$6:$O$185,Register!$A$6:$A$185,$A11,Register!$D$6:$D$185,H$7)))))) -> 2 | I11: =IF($A11="","",IF(COUNTIFS(Register!$A$6:$A$185,$A11,Register!$D$6:$D$185,I$7)>1,"Dup.",IF($C$5="Critical assets (target)",IF(COUNTIFS(Register!$A$6:$A$185,$A11,Register!$D$6:$D$185,I$7,Register!$Q$6:$Q$185,">=0")=0,"",SUMIFS(Register!$Q$6:$Q$185,Register!$A$6:$A$185,$A11,Register!$D$6:$D$185,I$7)),IF($C$5="Released today",IF(COUNTIFS(Register!$A$6:$A$185,$A11,Register!$D$6:$D$185,I$7,Register!$T$6:$T$185,">=0")=0,"",SUMIFS(Register!$T$6:$T$185,Register!$A$6:$A$185,$A11,Register!$D$6:$D$185,I$7)),IF(COUNTIFS(Register!$A$6:$A$185,$A11,Register!$D$6:$D$185,I$7,Register!$O$6:$O$185,">=0")=0,"",SUMIFS(Register!$O$6:$O$185,Register!$A$6:$A$185,$A11,Register!$D$6:$D$185,I$7)))))) -> 2 | J11: =IF($A11="","",IF(COUNTIFS(Register!$A$6:$A$185,$A11,Register!$D$6:$D$185,J$7)>1,"Dup.",IF($C$5="Critical assets (target)",IF(COUNTIFS(Register!$A$6:$A$185,$A11,Register!$D$6:$D$185,J$7,Register!$Q$6:$Q$185,">=0")=0,"",SUMIFS(Register!$Q$6:$Q$185,Register!$A$6:$A$185,$A11,Register!$D$6:$D$185,J$7)),IF($C$5="Released today",IF(COUNTIFS(Register!$A$6:$A$185,$A11,Register!$D$6:$D$185,J$7,Register!$T$6:$T$185,">=0")=0,"",SUMIFS(Register!$T$6:$T$185,Register!$A$6:$A$185,$A11,Register!$D$6:$D$185,J$7)),IF(COUNTIFS(Register!$A$6:$A$185,$A11,Register!$D$6:$D$185,J$7,Register!$O$6:$O$185,">=0")=0,"",SUMIFS(Register!$O$6:$O$185,Register!$A$6:$A$185,$A11,Register!$D$6:$D$185,J$7)))))) -> 2 | K11: =IF($A11="","",IF(COUNT(E11:J11)<6,"Incomplete",IF(AND(ISNUMBER(E11),E11<4),E$7,IF(AND(ISNUMBER(F11),F11<4),F$7,IF(AND(ISNUMBER(G11),G11<4),G$7,IF(AND(ISNUMBER(H11),H11<4),H$7,IF(AND(ISNUMBER(I11),I11<4),I$7,IF(AND(ISNUMBER(J11),J11<4),J$7,"None")))))))) -> Triage | L11: =IF($A11="","",COUNTIFS(Register!$A$6:$A$185,$A11,Register!$P$6:$P$185,"Above policy*")) -> 0 | M11: =IF($A11="","",IF(COUNTIF('Readiness gate'!$A$7:$A$36,$A11)<>1,"Incomplete",IFERROR(IF(VLOOKUP($A11,GateTab,9,FALSE())="","Incomplete",VLOOKUP($A11,GateTab,9,FALSE())),"Incomplete"))) -> Passed | N11: =IF($A11="","",SUMPRODUCT((Register!$A$6:$A$185=$A11)*(Register!$T$6:$T$185<>"")*(Register!$O$6:$O$185<>"")*(Register!$T$6:$T$185<Register!$O$6:$O$185))) -> 5
A12: =IF('Use cases'!$B$9="","",'Use cases'!$A$9) -> UC05 | B12: =IF($A12="","",'Use cases'!$B$9) -> Privileged account anomaly | C12: =IF($A12="","",'Use cases'!$C$9) -> Identity | D12: =IF($A12="","",'Use cases'!$E$9) -> Progressive | E12: =IF($A12="","",IF(COUNTIFS(Register!$A$6:$A$185,$A12,Register!$D$6:$D$185,E$7)>1,"Dup.",IF($C$5="Critical assets (target)",IF(COUNTIFS(Register!$A$6:$A$185,$A12,Register!$D$6:$D$185,E$7,Register!$Q$6:$Q$185,">=0")=0,"",SUMIFS(Register!$Q$6:$Q$185,Register!$A$6:$A$185,$A12,Register!$D$6:$D$185,E$7)),IF($C$5="Released today",IF(COUNTIFS(Register!$A$6:$A$185,$A12,Register!$D$6:$D$185,E$7,Register!$T$6:$T$185,">=0")=0,"",SUMIFS(Register!$T$6:$T$185,Register!$A$6:$A$185,$A12,Register!$D$6:$D$185,E$7)),IF(COUNTIFS(Register!$A$6:$A$185,$A12,Register!$D$6:$D$185,E$7,Register!$O$6:$O$185,">=0")=0,"",SUMIFS(Register!$O$6:$O$185,Register!$A$6:$A$185,$A12,Register!$D$6:$D$185,E$7)))))) -> 1 | F12: =IF($A12="","",IF(COUNTIFS(Register!$A$6:$A$185,$A12,Register!$D$6:$D$185,F$7)>1,"Dup.",IF($C$5="Critical assets (target)",IF(COUNTIFS(Register!$A$6:$A$185,$A12,Register!$D$6:$D$185,F$7,Register!$Q$6:$Q$185,">=0")=0,"",SUMIFS(Register!$Q$6:$Q$185,Register!$A$6:$A$185,$A12,Register!$D$6:$D$185,F$7)),IF($C$5="Released today",IF(COUNTIFS(Register!$A$6:$A$185,$A12,Register!$D$6:$D$185,F$7,Register!$T$6:$T$185,">=0")=0,"",SUMIFS(Register!$T$6:$T$185,Register!$A$6:$A$185,$A12,Register!$D$6:$D$185,F$7)),IF(COUNTIFS(Register!$A$6:$A$185,$A12,Register!$D$6:$D$185,F$7,Register!$O$6:$O$185,">=0")=0,"",SUMIFS(Register!$O$6:$O$185,Register!$A$6:$A$185,$A12,Register!$D$6:$D$185,F$7)))))) -> 1 | G12: =IF($A12="","",IF(COUNTIFS(Register!$A$6:$A$185,$A12,Register!$D$6:$D$185,G$7)>1,"Dup.",IF($C$5="Critical assets (target)",IF(COUNTIFS(Register!$A$6:$A$185,$A12,Register!$D$6:$D$185,G$7,Register!$Q$6:$Q$185,">=0")=0,"",SUMIFS(Register!$Q$6:$Q$185,Register!$A$6:$A$185,$A12,Register!$D$6:$D$185,G$7)),IF($C$5="Released today",IF(COUNTIFS(Register!$A$6:$A$185,$A12,Register!$D$6:$D$185,G$7,Register!$T$6:$T$185,">=0")=0,"",SUMIFS(Register!$T$6:$T$185,Register!$A$6:$A$185,$A12,Register!$D$6:$D$185,G$7)),IF(COUNTIFS(Register!$A$6:$A$185,$A12,Register!$D$6:$D$185,G$7,Register!$O$6:$O$185,">=0")=0,"",SUMIFS(Register!$O$6:$O$185,Register!$A$6:$A$185,$A12,Register!$D$6:$D$185,G$7)))))) -> 2 | H12: =IF($A12="","",IF(COUNTIFS(Register!$A$6:$A$185,$A12,Register!$D$6:$D$185,H$7)>1,"Dup.",IF($C$5="Critical assets (target)",IF(COUNTIFS(Register!$A$6:$A$185,$A12,Register!$D$6:$D$185,H$7,Register!$Q$6:$Q$185,">=0")=0,"",SUMIFS(Register!$Q$6:$Q$185,Register!$A$6:$A$185,$A12,Register!$D$6:$D$185,H$7)),IF($C$5="Released today",IF(COUNTIFS(Register!$A$6:$A$185,$A12,Register!$D$6:$D$185,H$7,Register!$T$6:$T$185,">=0")=0,"",SUMIFS(Register!$T$6:$T$185,Register!$A$6:$A$185,$A12,Register!$D$6:$D$185,H$7)),IF(COUNTIFS(Register!$A$6:$A$185,$A12,Register!$D$6:$D$185,H$7,Register!$O$6:$O$185,">=0")=0,"",SUMIFS(Register!$O$6:$O$185,Register!$A$6:$A$185,$A12,Register!$D$6:$D$185,H$7)))))) -> 1 | I12: =IF($A12="","",IF(COUNTIFS(Register!$A$6:$A$185,$A12,Register!$D$6:$D$185,I$7)>1,"Dup.",IF($C$5="Critical assets (target)",IF(COUNTIFS(Register!$A$6:$A$185,$A12,Register!$D$6:$D$185,I$7,Register!$Q$6:$Q$185,">=0")=0,"",SUMIFS(Register!$Q$6:$Q$185,Register!$A$6:$A$185,$A12,Register!$D$6:$D$185,I$7)),IF($C$5="Released today",IF(COUNTIFS(Register!$A$6:$A$185,$A12,Register!$D$6:$D$185,I$7,Register!$T$6:$T$185,">=0")=0,"",SUMIFS(Register!$T$6:$T$185,Register!$A$6:$A$185,$A12,Register!$D$6:$D$185,I$7)),IF(COUNTIFS(Register!$A$6:$A$185,$A12,Register!$D$6:$D$185,I$7,Register!$O$6:$O$185,">=0")=0,"",SUMIFS(Register!$O$6:$O$185,Register!$A$6:$A$185,$A12,Register!$D$6:$D$185,I$7)))))) -> 1 | J12: =IF($A12="","",IF(COUNTIFS(Register!$A$6:$A$185,$A12,Register!$D$6:$D$185,J$7)>1,"Dup.",IF($C$5="Critical assets (target)",IF(COUNTIFS(Register!$A$6:$A$185,$A12,Register!$D$6:$D$185,J$7,Register!$Q$6:$Q$185,">=0")=0,"",SUMIFS(Register!$Q$6:$Q$185,Register!$A$6:$A$185,$A12,Register!$D$6:$D$185,J$7)),IF($C$5="Released today",IF(COUNTIFS(Register!$A$6:$A$185,$A12,Register!$D$6:$D$185,J$7,Register!$T$6:$T$185,">=0")=0,"",SUMIFS(Register!$T$6:$T$185,Register!$A$6:$A$185,$A12,Register!$D$6:$D$185,J$7)),IF(COUNTIFS(Register!$A$6:$A$185,$A12,Register!$D$6:$D$185,J$7,Register!$O$6:$O$185,">=0")=0,"",SUMIFS(Register!$O$6:$O$185,Register!$A$6:$A$185,$A12,Register!$D$6:$D$185,J$7)))))) -> 1 | K12: =IF($A12="","",IF(COUNT(E12:J12)<6,"Incomplete",IF(AND(ISNUMBER(E12),E12<4),E$7,IF(AND(ISNUMBER(F12),F12<4),F$7,IF(AND(ISNUMBER(G12),G12<4),G$7,IF(AND(ISNUMBER(H12),H12<4),H$7,IF(AND(ISNUMBER(I12),I12<4),I$7,IF(AND(ISNUMBER(J12),J12<4),J$7,"None")))))))) -> Enrich | L12: =IF($A12="","",COUNTIFS(Register!$A$6:$A$185,$A12,Register!$P$6:$P$185,"Above policy*")) -> 0 | M12: =IF($A12="","",IF(COUNTIF('Readiness gate'!$A$7:$A$36,$A12)<>1,"Incomplete",IFERROR(IF(VLOOKUP($A12,GateTab,9,FALSE())="","Incomplete",VLOOKUP($A12,GateTab,9,FALSE())),"Incomplete"))) -> Not passed | N12: =IF($A12="","",SUMPRODUCT((Register!$A$6:$A$185=$A12)*(Register!$T$6:$T$185<>"")*(Register!$O$6:$O$185<>"")*(Register!$T$6:$T$185<Register!$O$6:$O$185))) -> 6
A13: =IF('Use cases'!$B$10="","",'Use cases'!$A$10) -> UC06 | B13: =IF($A13="","",'Use cases'!$B$10) -> Token theft and replay | C13: =IF($A13="","",'Use cases'!$C$10) -> Identity | D13: =IF($A13="","",'Use cases'!$E$10) -> Progressive | E13: =IF($A13="","",IF(COUNTIFS(Register!$A$6:$A$185,$A13,Register!$D$6:$D$185,E$7)>1,"Dup.",IF($C$5="Critical assets (target)",IF(COUNTIFS(Register!$A$6:$A$185,$A13,Register!$D$6:$D$185,E$7,Register!$Q$6:$Q$185,">=0")=0,"",SUMIFS(Register!$Q$6:$Q$185,Register!$A$6:$A$185,$A13,Register!$D$6:$D$185,E$7)),IF($C$5="Released today",IF(COUNTIFS(Register!$A$6:$A$185,$A13,Register!$D$6:$D$185,E$7,Register!$T$6:$T$185,">=0")=0,"",SUMIFS(Register!$T$6:$T$185,Register!$A$6:$A$185,$A13,Register!$D$6:$D$185,E$7)),IF(COUNTIFS(Register!$A$6:$A$185,$A13,Register!$D$6:$D$185,E$7,Register!$O$6:$O$185,">=0")=0,"",SUMIFS(Register!$O$6:$O$185,Register!$A$6:$A$185,$A13,Register!$D$6:$D$185,E$7)))))) -> 4 | F13: =IF($A13="","",IF(COUNTIFS(Register!$A$6:$A$185,$A13,Register!$D$6:$D$185,F$7)>1,"Dup.",IF($C$5="Critical assets (target)",IF(COUNTIFS(Register!$A$6:$A$185,$A13,Register!$D$6:$D$185,F$7,Register!$Q$6:$Q$185,">=0")=0,"",SUMIFS(Register!$Q$6:$Q$185,Register!$A$6:$A$185,$A13,Register!$D$6:$D$185,F$7)),IF($C$5="Released today",IF(COUNTIFS(Register!$A$6:$A$185,$A13,Register!$D$6:$D$185,F$7,Register!$T$6:$T$185,">=0")=0,"",SUMIFS(Register!$T$6:$T$185,Register!$A$6:$A$185,$A13,Register!$D$6:$D$185,F$7)),IF(COUNTIFS(Register!$A$6:$A$185,$A13,Register!$D$6:$D$185,F$7,Register!$O$6:$O$185,">=0")=0,"",SUMIFS(Register!$O$6:$O$185,Register!$A$6:$A$185,$A13,Register!$D$6:$D$185,F$7)))))) -> 2 | G13: =IF($A13="","",IF(COUNTIFS(Register!$A$6:$A$185,$A13,Register!$D$6:$D$185,G$7)>1,"Dup.",IF($C$5="Critical assets (target)",IF(COUNTIFS(Register!$A$6:$A$185,$A13,Register!$D$6:$D$185,G$7,Register!$Q$6:$Q$185,">=0")=0,"",SUMIFS(Register!$Q$6:$Q$185,Register!$A$6:$A$185,$A13,Register!$D$6:$D$185,G$7)),IF($C$5="Released today",IF(COUNTIFS(Register!$A$6:$A$185,$A13,Register!$D$6:$D$185,G$7,Register!$T$6:$T$185,">=0")=0,"",SUMIFS(Register!$T$6:$T$185,Register!$A$6:$A$185,$A13,Register!$D$6:$D$185,G$7)),IF(COUNTIFS(Register!$A$6:$A$185,$A13,Register!$D$6:$D$185,G$7,Register!$O$6:$O$185,">=0")=0,"",SUMIFS(Register!$O$6:$O$185,Register!$A$6:$A$185,$A13,Register!$D$6:$D$185,G$7)))))) -> 3 | H13: =IF($A13="","",IF(COUNTIFS(Register!$A$6:$A$185,$A13,Register!$D$6:$D$185,H$7)>1,"Dup.",IF($C$5="Critical assets (target)",IF(COUNTIFS(Register!$A$6:$A$185,$A13,Register!$D$6:$D$185,H$7,Register!$Q$6:$Q$185,">=0")=0,"",SUMIFS(Register!$Q$6:$Q$185,Register!$A$6:$A$185,$A13,Register!$D$6:$D$185,H$7)),IF($C$5="Released today",IF(COUNTIFS(Register!$A$6:$A$185,$A13,Register!$D$6:$D$185,H$7,Register!$T$6:$T$185,">=0")=0,"",SUMIFS(Register!$T$6:$T$185,Register!$A$6:$A$185,$A13,Register!$D$6:$D$185,H$7)),IF(COUNTIFS(Register!$A$6:$A$185,$A13,Register!$D$6:$D$185,H$7,Register!$O$6:$O$185,">=0")=0,"",SUMIFS(Register!$O$6:$O$185,Register!$A$6:$A$185,$A13,Register!$D$6:$D$185,H$7)))))) -> 2 | I13: =IF($A13="","",IF(COUNTIFS(Register!$A$6:$A$185,$A13,Register!$D$6:$D$185,I$7)>1,"Dup.",IF($C$5="Critical assets (target)",IF(COUNTIFS(Register!$A$6:$A$185,$A13,Register!$D$6:$D$185,I$7,Register!$Q$6:$Q$185,">=0")=0,"",SUMIFS(Register!$Q$6:$Q$185,Register!$A$6:$A$185,$A13,Register!$D$6:$D$185,I$7)),IF($C$5="Released today",IF(COUNTIFS(Register!$A$6:$A$185,$A13,Register!$D$6:$D$185,I$7,Register!$T$6:$T$185,">=0")=0,"",SUMIFS(Register!$T$6:$T$185,Register!$A$6:$A$185,$A13,Register!$D$6:$D$185,I$7)),IF(COUNTIFS(Register!$A$6:$A$185,$A13,Register!$D$6:$D$185,I$7,Register!$O$6:$O$185,">=0")=0,"",SUMIFS(Register!$O$6:$O$185,Register!$A$6:$A$185,$A13,Register!$D$6:$D$185,I$7)))))) -> 2 | J13: =IF($A13="","",IF(COUNTIFS(Register!$A$6:$A$185,$A13,Register!$D$6:$D$185,J$7)>1,"Dup.",IF($C$5="Critical assets (target)",IF(COUNTIFS(Register!$A$6:$A$185,$A13,Register!$D$6:$D$185,J$7,Register!$Q$6:$Q$185,">=0")=0,"",SUMIFS(Register!$Q$6:$Q$185,Register!$A$6:$A$185,$A13,Register!$D$6:$D$185,J$7)),IF($C$5="Released today",IF(COUNTIFS(Register!$A$6:$A$185,$A13,Register!$D$6:$D$185,J$7,Register!$T$6:$T$185,">=0")=0,"",SUMIFS(Register!$T$6:$T$185,Register!$A$6:$A$185,$A13,Register!$D$6:$D$185,J$7)),IF(COUNTIFS(Register!$A$6:$A$185,$A13,Register!$D$6:$D$185,J$7,Register!$O$6:$O$185,">=0")=0,"",SUMIFS(Register!$O$6:$O$185,Register!$A$6:$A$185,$A13,Register!$D$6:$D$185,J$7)))))) -> 2 | K13: =IF($A13="","",IF(COUNT(E13:J13)<6,"Incomplete",IF(AND(ISNUMBER(E13),E13<4),E$7,IF(AND(ISNUMBER(F13),F13<4),F$7,IF(AND(ISNUMBER(G13),G13<4),G$7,IF(AND(ISNUMBER(H13),H13<4),H$7,IF(AND(ISNUMBER(I13),I13<4),I$7,IF(AND(ISNUMBER(J13),J13<4),J$7,"None")))))))) -> Triage | L13: =IF($A13="","",COUNTIFS(Register!$A$6:$A$185,$A13,Register!$P$6:$P$185,"Above policy*")) -> 0 | M13: =IF($A13="","",IF(COUNTIF('Readiness gate'!$A$7:$A$36,$A13)<>1,"Incomplete",IFERROR(IF(VLOOKUP($A13,GateTab,9,FALSE())="","Incomplete",VLOOKUP($A13,GateTab,9,FALSE())),"Incomplete"))) -> Passed | N13: =IF($A13="","",SUMPRODUCT((Register!$A$6:$A$185=$A13)*(Register!$T$6:$T$185<>"")*(Register!$O$6:$O$185<>"")*(Register!$T$6:$T$185<Register!$O$6:$O$185))) -> 5
A14: =IF('Use cases'!$B$11="","",'Use cases'!$A$11) -> UC07 | B14: =IF($A14="","",'Use cases'!$B$11) -> Endpoint malware containment | C14: =IF($A14="","",'Use cases'!$C$11) -> Endpoint | D14: =IF($A14="","",'Use cases'!$E$11) -> Progressive | E14: =IF($A14="","",IF(COUNTIFS(Register!$A$6:$A$185,$A14,Register!$D$6:$D$185,E$7)>1,"Dup.",IF($C$5="Critical assets (target)",IF(COUNTIFS(Register!$A$6:$A$185,$A14,Register!$D$6:$D$185,E$7,Register!$Q$6:$Q$185,">=0")=0,"",SUMIFS(Register!$Q$6:$Q$185,Register!$A$6:$A$185,$A14,Register!$D$6:$D$185,E$7)),IF($C$5="Released today",IF(COUNTIFS(Register!$A$6:$A$185,$A14,Register!$D$6:$D$185,E$7,Register!$T$6:$T$185,">=0")=0,"",SUMIFS(Register!$T$6:$T$185,Register!$A$6:$A$185,$A14,Register!$D$6:$D$185,E$7)),IF(COUNTIFS(Register!$A$6:$A$185,$A14,Register!$D$6:$D$185,E$7,Register!$O$6:$O$185,">=0")=0,"",SUMIFS(Register!$O$6:$O$185,Register!$A$6:$A$185,$A14,Register!$D$6:$D$185,E$7)))))) -> 4 | F14: =IF($A14="","",IF(COUNTIFS(Register!$A$6:$A$185,$A14,Register!$D$6:$D$185,F$7)>1,"Dup.",IF($C$5="Critical assets (target)",IF(COUNTIFS(Register!$A$6:$A$185,$A14,Register!$D$6:$D$185,F$7,Register!$Q$6:$Q$185,">=0")=0,"",SUMIFS(Register!$Q$6:$Q$185,Register!$A$6:$A$185,$A14,Register!$D$6:$D$185,F$7)),IF($C$5="Released today",IF(COUNTIFS(Register!$A$6:$A$185,$A14,Register!$D$6:$D$185,F$7,Register!$T$6:$T$185,">=0")=0,"",SUMIFS(Register!$T$6:$T$185,Register!$A$6:$A$185,$A14,Register!$D$6:$D$185,F$7)),IF(COUNTIFS(Register!$A$6:$A$185,$A14,Register!$D$6:$D$185,F$7,Register!$O$6:$O$185,">=0")=0,"",SUMIFS(Register!$O$6:$O$185,Register!$A$6:$A$185,$A14,Register!$D$6:$D$185,F$7)))))) -> 2 | G14: =IF($A14="","",IF(COUNTIFS(Register!$A$6:$A$185,$A14,Register!$D$6:$D$185,G$7)>1,"Dup.",IF($C$5="Critical assets (target)",IF(COUNTIFS(Register!$A$6:$A$185,$A14,Register!$D$6:$D$185,G$7,Register!$Q$6:$Q$185,">=0")=0,"",SUMIFS(Register!$Q$6:$Q$185,Register!$A$6:$A$185,$A14,Register!$D$6:$D$185,G$7)),IF($C$5="Released today",IF(COUNTIFS(Register!$A$6:$A$185,$A14,Register!$D$6:$D$185,G$7,Register!$T$6:$T$185,">=0")=0,"",SUMIFS(Register!$T$6:$T$185,Register!$A$6:$A$185,$A14,Register!$D$6:$D$185,G$7)),IF(COUNTIFS(Register!$A$6:$A$185,$A14,Register!$D$6:$D$185,G$7,Register!$O$6:$O$185,">=0")=0,"",SUMIFS(Register!$O$6:$O$185,Register!$A$6:$A$185,$A14,Register!$D$6:$D$185,G$7)))))) -> 4 | H14: =IF($A14="","",IF(COUNTIFS(Register!$A$6:$A$185,$A14,Register!$D$6:$D$185,H$7)>1,"Dup.",IF($C$5="Critical assets (target)",IF(COUNTIFS(Register!$A$6:$A$185,$A14,Register!$D$6:$D$185,H$7,Register!$Q$6:$Q$185,">=0")=0,"",SUMIFS(Register!$Q$6:$Q$185,Register!$A$6:$A$185,$A14,Register!$D$6:$D$185,H$7)),IF($C$5="Released today",IF(COUNTIFS(Register!$A$6:$A$185,$A14,Register!$D$6:$D$185,H$7,Register!$T$6:$T$185,">=0")=0,"",SUMIFS(Register!$T$6:$T$185,Register!$A$6:$A$185,$A14,Register!$D$6:$D$185,H$7)),IF(COUNTIFS(Register!$A$6:$A$185,$A14,Register!$D$6:$D$185,H$7,Register!$O$6:$O$185,">=0")=0,"",SUMIFS(Register!$O$6:$O$185,Register!$A$6:$A$185,$A14,Register!$D$6:$D$185,H$7)))))) -> 2 | I14: =IF($A14="","",IF(COUNTIFS(Register!$A$6:$A$185,$A14,Register!$D$6:$D$185,I$7)>1,"Dup.",IF($C$5="Critical assets (target)",IF(COUNTIFS(Register!$A$6:$A$185,$A14,Register!$D$6:$D$185,I$7,Register!$Q$6:$Q$185,">=0")=0,"",SUMIFS(Register!$Q$6:$Q$185,Register!$A$6:$A$185,$A14,Register!$D$6:$D$185,I$7)),IF($C$5="Released today",IF(COUNTIFS(Register!$A$6:$A$185,$A14,Register!$D$6:$D$185,I$7,Register!$T$6:$T$185,">=0")=0,"",SUMIFS(Register!$T$6:$T$185,Register!$A$6:$A$185,$A14,Register!$D$6:$D$185,I$7)),IF(COUNTIFS(Register!$A$6:$A$185,$A14,Register!$D$6:$D$185,I$7,Register!$O$6:$O$185,">=0")=0,"",SUMIFS(Register!$O$6:$O$185,Register!$A$6:$A$185,$A14,Register!$D$6:$D$185,I$7)))))) -> 2 | J14: =IF($A14="","",IF(COUNTIFS(Register!$A$6:$A$185,$A14,Register!$D$6:$D$185,J$7)>1,"Dup.",IF($C$5="Critical assets (target)",IF(COUNTIFS(Register!$A$6:$A$185,$A14,Register!$D$6:$D$185,J$7,Register!$Q$6:$Q$185,">=0")=0,"",SUMIFS(Register!$Q$6:$Q$185,Register!$A$6:$A$185,$A14,Register!$D$6:$D$185,J$7)),IF($C$5="Released today",IF(COUNTIFS(Register!$A$6:$A$185,$A14,Register!$D$6:$D$185,J$7,Register!$T$6:$T$185,">=0")=0,"",SUMIFS(Register!$T$6:$T$185,Register!$A$6:$A$185,$A14,Register!$D$6:$D$185,J$7)),IF(COUNTIFS(Register!$A$6:$A$185,$A14,Register!$D$6:$D$185,J$7,Register!$O$6:$O$185,">=0")=0,"",SUMIFS(Register!$O$6:$O$185,Register!$A$6:$A$185,$A14,Register!$D$6:$D$185,J$7)))))) -> 2 | K14: =IF($A14="","",IF(COUNT(E14:J14)<6,"Incomplete",IF(AND(ISNUMBER(E14),E14<4),E$7,IF(AND(ISNUMBER(F14),F14<4),F$7,IF(AND(ISNUMBER(G14),G14<4),G$7,IF(AND(ISNUMBER(H14),H14<4),H$7,IF(AND(ISNUMBER(I14),I14<4),I$7,IF(AND(ISNUMBER(J14),J14<4),J$7,"None")))))))) -> Triage | L14: =IF($A14="","",COUNTIFS(Register!$A$6:$A$185,$A14,Register!$P$6:$P$185,"Above policy*")) -> 0 | M14: =IF($A14="","",IF(COUNTIF('Readiness gate'!$A$7:$A$36,$A14)<>1,"Incomplete",IFERROR(IF(VLOOKUP($A14,GateTab,9,FALSE())="","Incomplete",VLOOKUP($A14,GateTab,9,FALSE())),"Incomplete"))) -> Passed | N14: =IF($A14="","",SUMPRODUCT((Register!$A$6:$A$185=$A14)*(Register!$T$6:$T$185<>"")*(Register!$O$6:$O$185<>"")*(Register!$T$6:$T$185<Register!$O$6:$O$185))) -> 4
A15: =IF('Use cases'!$B$12="","",'Use cases'!$A$12) -> UC08 | B15: =IF($A15="","",'Use cases'!$B$12) -> Early ransomware indicators | C15: =IF($A15="","",'Use cases'!$C$12) -> Endpoint | D15: =IF($A15="","",'Use cases'!$E$12) -> Progressive | E15: =IF($A15="","",IF(COUNTIFS(Register!$A$6:$A$185,$A15,Register!$D$6:$D$185,E$7)>1,"Dup.",IF($C$5="Critical assets (target)",IF(COUNTIFS(Register!$A$6:$A$185,$A15,Register!$D$6:$D$185,E$7,Register!$Q$6:$Q$185,">=0")=0,"",SUMIFS(Register!$Q$6:$Q$185,Register!$A$6:$A$185,$A15,Register!$D$6:$D$185,E$7)),IF($C$5="Released today",IF(COUNTIFS(Register!$A$6:$A$185,$A15,Register!$D$6:$D$185,E$7,Register!$T$6:$T$185,">=0")=0,"",SUMIFS(Register!$T$6:$T$185,Register!$A$6:$A$185,$A15,Register!$D$6:$D$185,E$7)),IF(COUNTIFS(Register!$A$6:$A$185,$A15,Register!$D$6:$D$185,E$7,Register!$O$6:$O$185,">=0")=0,"",SUMIFS(Register!$O$6:$O$185,Register!$A$6:$A$185,$A15,Register!$D$6:$D$185,E$7)))))) -> 1 | F15: =IF($A15="","",IF(COUNTIFS(Register!$A$6:$A$185,$A15,Register!$D$6:$D$185,F$7)>1,"Dup.",IF($C$5="Critical assets (target)",IF(COUNTIFS(Register!$A$6:$A$185,$A15,Register!$D$6:$D$185,F$7,Register!$Q$6:$Q$185,">=0")=0,"",SUMIFS(Register!$Q$6:$Q$185,Register!$A$6:$A$185,$A15,Register!$D$6:$D$185,F$7)),IF($C$5="Released today",IF(COUNTIFS(Register!$A$6:$A$185,$A15,Register!$D$6:$D$185,F$7,Register!$T$6:$T$185,">=0")=0,"",SUMIFS(Register!$T$6:$T$185,Register!$A$6:$A$185,$A15,Register!$D$6:$D$185,F$7)),IF(COUNTIFS(Register!$A$6:$A$185,$A15,Register!$D$6:$D$185,F$7,Register!$O$6:$O$185,">=0")=0,"",SUMIFS(Register!$O$6:$O$185,Register!$A$6:$A$185,$A15,Register!$D$6:$D$185,F$7)))))) -> 1 | G15: =IF($A15="","",IF(COUNTIFS(Register!$A$6:$A$185,$A15,Register!$D$6:$D$185,G$7)>1,"Dup.",IF($C$5="Critical assets (target)",IF(COUNTIFS(Register!$A$6:$A$185,$A15,Register!$D$6:$D$185,G$7,Register!$Q$6:$Q$185,">=0")=0,"",SUMIFS(Register!$Q$6:$Q$185,Register!$A$6:$A$185,$A15,Register!$D$6:$D$185,G$7)),IF($C$5="Released today",IF(COUNTIFS(Register!$A$6:$A$185,$A15,Register!$D$6:$D$185,G$7,Register!$T$6:$T$185,">=0")=0,"",SUMIFS(Register!$T$6:$T$185,Register!$A$6:$A$185,$A15,Register!$D$6:$D$185,G$7)),IF(COUNTIFS(Register!$A$6:$A$185,$A15,Register!$D$6:$D$185,G$7,Register!$O$6:$O$185,">=0")=0,"",SUMIFS(Register!$O$6:$O$185,Register!$A$6:$A$185,$A15,Register!$D$6:$D$185,G$7)))))) -> 2 | H15: =IF($A15="","",IF(COUNTIFS(Register!$A$6:$A$185,$A15,Register!$D$6:$D$185,H$7)>1,"Dup.",IF($C$5="Critical assets (target)",IF(COUNTIFS(Register!$A$6:$A$185,$A15,Register!$D$6:$D$185,H$7,Register!$Q$6:$Q$185,">=0")=0,"",SUMIFS(Register!$Q$6:$Q$185,Register!$A$6:$A$185,$A15,Register!$D$6:$D$185,H$7)),IF($C$5="Released today",IF(COUNTIFS(Register!$A$6:$A$185,$A15,Register!$D$6:$D$185,H$7,Register!$T$6:$T$185,">=0")=0,"",SUMIFS(Register!$T$6:$T$185,Register!$A$6:$A$185,$A15,Register!$D$6:$D$185,H$7)),IF(COUNTIFS(Register!$A$6:$A$185,$A15,Register!$D$6:$D$185,H$7,Register!$O$6:$O$185,">=0")=0,"",SUMIFS(Register!$O$6:$O$185,Register!$A$6:$A$185,$A15,Register!$D$6:$D$185,H$7)))))) -> 1 | I15: =IF($A15="","",IF(COUNTIFS(Register!$A$6:$A$185,$A15,Register!$D$6:$D$185,I$7)>1,"Dup.",IF($C$5="Critical assets (target)",IF(COUNTIFS(Register!$A$6:$A$185,$A15,Register!$D$6:$D$185,I$7,Register!$Q$6:$Q$185,">=0")=0,"",SUMIFS(Register!$Q$6:$Q$185,Register!$A$6:$A$185,$A15,Register!$D$6:$D$185,I$7)),IF($C$5="Released today",IF(COUNTIFS(Register!$A$6:$A$185,$A15,Register!$D$6:$D$185,I$7,Register!$T$6:$T$185,">=0")=0,"",SUMIFS(Register!$T$6:$T$185,Register!$A$6:$A$185,$A15,Register!$D$6:$D$185,I$7)),IF(COUNTIFS(Register!$A$6:$A$185,$A15,Register!$D$6:$D$185,I$7,Register!$O$6:$O$185,">=0")=0,"",SUMIFS(Register!$O$6:$O$185,Register!$A$6:$A$185,$A15,Register!$D$6:$D$185,I$7)))))) -> 1 | J15: =IF($A15="","",IF(COUNTIFS(Register!$A$6:$A$185,$A15,Register!$D$6:$D$185,J$7)>1,"Dup.",IF($C$5="Critical assets (target)",IF(COUNTIFS(Register!$A$6:$A$185,$A15,Register!$D$6:$D$185,J$7,Register!$Q$6:$Q$185,">=0")=0,"",SUMIFS(Register!$Q$6:$Q$185,Register!$A$6:$A$185,$A15,Register!$D$6:$D$185,J$7)),IF($C$5="Released today",IF(COUNTIFS(Register!$A$6:$A$185,$A15,Register!$D$6:$D$185,J$7,Register!$T$6:$T$185,">=0")=0,"",SUMIFS(Register!$T$6:$T$185,Register!$A$6:$A$185,$A15,Register!$D$6:$D$185,J$7)),IF(COUNTIFS(Register!$A$6:$A$185,$A15,Register!$D$6:$D$185,J$7,Register!$O$6:$O$185,">=0")=0,"",SUMIFS(Register!$O$6:$O$185,Register!$A$6:$A$185,$A15,Register!$D$6:$D$185,J$7)))))) -> 1 | K15: =IF($A15="","",IF(COUNT(E15:J15)<6,"Incomplete",IF(AND(ISNUMBER(E15),E15<4),E$7,IF(AND(ISNUMBER(F15),F15<4),F$7,IF(AND(ISNUMBER(G15),G15<4),G$7,IF(AND(ISNUMBER(H15),H15<4),H$7,IF(AND(ISNUMBER(I15),I15<4),I$7,IF(AND(ISNUMBER(J15),J15<4),J$7,"None")))))))) -> Enrich | L15: =IF($A15="","",COUNTIFS(Register!$A$6:$A$185,$A15,Register!$P$6:$P$185,"Above policy*")) -> 0 | M15: =IF($A15="","",IF(COUNTIF('Readiness gate'!$A$7:$A$36,$A15)<>1,"Incomplete",IFERROR(IF(VLOOKUP($A15,GateTab,9,FALSE())="","Incomplete",VLOOKUP($A15,GateTab,9,FALSE())),"Incomplete"))) -> Not passed | N15: =IF($A15="","",SUMPRODUCT((Register!$A$6:$A$185=$A15)*(Register!$T$6:$T$185<>"")*(Register!$O$6:$O$185<>"")*(Register!$T$6:$T$185<Register!$O$6:$O$185))) -> 6
A16: =IF('Use cases'!$B$13="","",'Use cases'!$A$13) -> UC09 | B16: =IF($A16="","",'Use cases'!$B$13) -> C2 beaconing | C16: =IF($A16="","",'Use cases'!$C$13) -> Network | D16: =IF($A16="","",'Use cases'!$E$13) -> Progressive | E16: =IF($A16="","",IF(COUNTIFS(Register!$A$6:$A$185,$A16,Register!$D$6:$D$185,E$7)>1,"Dup.",IF($C$5="Critical assets (target)",IF(COUNTIFS(Register!$A$6:$A$185,$A16,Register!$D$6:$D$185,E$7,Register!$Q$6:$Q$185,">=0")=0,"",SUMIFS(Register!$Q$6:$Q$185,Register!$A$6:$A$185,$A16,Register!$D$6:$D$185,E$7)),IF($C$5="Released today",IF(COUNTIFS(Register!$A$6:$A$185,$A16,Register!$D$6:$D$185,E$7,Register!$T$6:$T$185,">=0")=0,"",SUMIFS(Register!$T$6:$T$185,Register!$A$6:$A$185,$A16,Register!$D$6:$D$185,E$7)),IF(COUNTIFS(Register!$A$6:$A$185,$A16,Register!$D$6:$D$185,E$7,Register!$O$6:$O$185,">=0")=0,"",SUMIFS(Register!$O$6:$O$185,Register!$A$6:$A$185,$A16,Register!$D$6:$D$185,E$7)))))) -> 4 | F16: =IF($A16="","",IF(COUNTIFS(Register!$A$6:$A$185,$A16,Register!$D$6:$D$185,F$7)>1,"Dup.",IF($C$5="Critical assets (target)",IF(COUNTIFS(Register!$A$6:$A$185,$A16,Register!$D$6:$D$185,F$7,Register!$Q$6:$Q$185,">=0")=0,"",SUMIFS(Register!$Q$6:$Q$185,Register!$A$6:$A$185,$A16,Register!$D$6:$D$185,F$7)),IF($C$5="Released today",IF(COUNTIFS(Register!$A$6:$A$185,$A16,Register!$D$6:$D$185,F$7,Register!$T$6:$T$185,">=0")=0,"",SUMIFS(Register!$T$6:$T$185,Register!$A$6:$A$185,$A16,Register!$D$6:$D$185,F$7)),IF(COUNTIFS(Register!$A$6:$A$185,$A16,Register!$D$6:$D$185,F$7,Register!$O$6:$O$185,">=0")=0,"",SUMIFS(Register!$O$6:$O$185,Register!$A$6:$A$185,$A16,Register!$D$6:$D$185,F$7)))))) -> 2 | G16: =IF($A16="","",IF(COUNTIFS(Register!$A$6:$A$185,$A16,Register!$D$6:$D$185,G$7)>1,"Dup.",IF($C$5="Critical assets (target)",IF(COUNTIFS(Register!$A$6:$A$185,$A16,Register!$D$6:$D$185,G$7,Register!$Q$6:$Q$185,">=0")=0,"",SUMIFS(Register!$Q$6:$Q$185,Register!$A$6:$A$185,$A16,Register!$D$6:$D$185,G$7)),IF($C$5="Released today",IF(COUNTIFS(Register!$A$6:$A$185,$A16,Register!$D$6:$D$185,G$7,Register!$T$6:$T$185,">=0")=0,"",SUMIFS(Register!$T$6:$T$185,Register!$A$6:$A$185,$A16,Register!$D$6:$D$185,G$7)),IF(COUNTIFS(Register!$A$6:$A$185,$A16,Register!$D$6:$D$185,G$7,Register!$O$6:$O$185,">=0")=0,"",SUMIFS(Register!$O$6:$O$185,Register!$A$6:$A$185,$A16,Register!$D$6:$D$185,G$7)))))) -> 4 | H16: =IF($A16="","",IF(COUNTIFS(Register!$A$6:$A$185,$A16,Register!$D$6:$D$185,H$7)>1,"Dup.",IF($C$5="Critical assets (target)",IF(COUNTIFS(Register!$A$6:$A$185,$A16,Register!$D$6:$D$185,H$7,Register!$Q$6:$Q$185,">=0")=0,"",SUMIFS(Register!$Q$6:$Q$185,Register!$A$6:$A$185,$A16,Register!$D$6:$D$185,H$7)),IF($C$5="Released today",IF(COUNTIFS(Register!$A$6:$A$185,$A16,Register!$D$6:$D$185,H$7,Register!$T$6:$T$185,">=0")=0,"",SUMIFS(Register!$T$6:$T$185,Register!$A$6:$A$185,$A16,Register!$D$6:$D$185,H$7)),IF(COUNTIFS(Register!$A$6:$A$185,$A16,Register!$D$6:$D$185,H$7,Register!$O$6:$O$185,">=0")=0,"",SUMIFS(Register!$O$6:$O$185,Register!$A$6:$A$185,$A16,Register!$D$6:$D$185,H$7)))))) -> 2 | I16: =IF($A16="","",IF(COUNTIFS(Register!$A$6:$A$185,$A16,Register!$D$6:$D$185,I$7)>1,"Dup.",IF($C$5="Critical assets (target)",IF(COUNTIFS(Register!$A$6:$A$185,$A16,Register!$D$6:$D$185,I$7,Register!$Q$6:$Q$185,">=0")=0,"",SUMIFS(Register!$Q$6:$Q$185,Register!$A$6:$A$185,$A16,Register!$D$6:$D$185,I$7)),IF($C$5="Released today",IF(COUNTIFS(Register!$A$6:$A$185,$A16,Register!$D$6:$D$185,I$7,Register!$T$6:$T$185,">=0")=0,"",SUMIFS(Register!$T$6:$T$185,Register!$A$6:$A$185,$A16,Register!$D$6:$D$185,I$7)),IF(COUNTIFS(Register!$A$6:$A$185,$A16,Register!$D$6:$D$185,I$7,Register!$O$6:$O$185,">=0")=0,"",SUMIFS(Register!$O$6:$O$185,Register!$A$6:$A$185,$A16,Register!$D$6:$D$185,I$7)))))) -> 2 | J16: =IF($A16="","",IF(COUNTIFS(Register!$A$6:$A$185,$A16,Register!$D$6:$D$185,J$7)>1,"Dup.",IF($C$5="Critical assets (target)",IF(COUNTIFS(Register!$A$6:$A$185,$A16,Register!$D$6:$D$185,J$7,Register!$Q$6:$Q$185,">=0")=0,"",SUMIFS(Register!$Q$6:$Q$185,Register!$A$6:$A$185,$A16,Register!$D$6:$D$185,J$7)),IF($C$5="Released today",IF(COUNTIFS(Register!$A$6:$A$185,$A16,Register!$D$6:$D$185,J$7,Register!$T$6:$T$185,">=0")=0,"",SUMIFS(Register!$T$6:$T$185,Register!$A$6:$A$185,$A16,Register!$D$6:$D$185,J$7)),IF(COUNTIFS(Register!$A$6:$A$185,$A16,Register!$D$6:$D$185,J$7,Register!$O$6:$O$185,">=0")=0,"",SUMIFS(Register!$O$6:$O$185,Register!$A$6:$A$185,$A16,Register!$D$6:$D$185,J$7)))))) -> 2 | K16: =IF($A16="","",IF(COUNT(E16:J16)<6,"Incomplete",IF(AND(ISNUMBER(E16),E16<4),E$7,IF(AND(ISNUMBER(F16),F16<4),F$7,IF(AND(ISNUMBER(G16),G16<4),G$7,IF(AND(ISNUMBER(H16),H16<4),H$7,IF(AND(ISNUMBER(I16),I16<4),I$7,IF(AND(ISNUMBER(J16),J16<4),J$7,"None")))))))) -> Triage | L16: =IF($A16="","",COUNTIFS(Register!$A$6:$A$185,$A16,Register!$P$6:$P$185,"Above policy*")) -> 0 | M16: =IF($A16="","",IF(COUNTIF('Readiness gate'!$A$7:$A$36,$A16)<>1,"Incomplete",IFERROR(IF(VLOOKUP($A16,GateTab,9,FALSE())="","Incomplete",VLOOKUP($A16,GateTab,9,FALSE())),"Incomplete"))) -> Passed | N16: =IF($A16="","",SUMPRODUCT((Register!$A$6:$A$185=$A16)*(Register!$T$6:$T$185<>"")*(Register!$O$6:$O$185<>"")*(Register!$T$6:$T$185<Register!$O$6:$O$185))) -> 4
